2020-11-14 18:55:45,540,540 asyncio DEBUG Using selector: KqueueSelector
2020-11-14 18:59:49,608,608 asyncio DEBUG Using selector: KqueueSelector
2020-11-14 19:00:02,978,978 asyncio DEBUG Using selector: KqueueSelector
2020-11-14 19:04:09,544,544 asyncio DEBUG Using selector: KqueueSelector
2020-11-14 20:21:41,286,286 django.utils.autoreload INFO /Users/mhope/Documents/projects/beta-survey-django/beta-survey-django/user_app/views.py changed, reloading.
2020-11-14 20:21:41,297,297 asyncio DEBUG Using selector: KqueueSelector
2020-11-14 20:21:45,047,47 django.utils.autoreload INFO /Users/mhope/Documents/projects/beta-survey-django/beta-survey-django/user_app/views.py changed, reloading.
2020-11-14 20:21:45,048,48 asyncio DEBUG Using selector: KqueueSelector
2020-11-14 20:21:49,027,27 django.utils.autoreload INFO /Users/mhope/Documents/projects/beta-survey-django/beta-survey-django/user_app/views.py changed, reloading.
2020-11-14 20:21:49,028,28 asyncio DEBUG Using selector: KqueueSelector
2020-11-14 20:29:34,223,223 django.utils.autoreload INFO /Users/mhope/Documents/projects/beta-survey-django/beta-survey-django/user_app/views.py changed, reloading.
2020-11-14 20:29:34,229,229 asyncio DEBUG Using selector: KqueueSelector
2020-11-14 20:30:38,655,655 django.utils.autoreload INFO /Users/mhope/Documents/projects/beta-survey-django/beta-survey-django/user_app/views.py changed, reloading.
2020-11-14 20:30:38,657,657 asyncio DEBUG Using selector: KqueueSelector
2020-11-14 20:30:58,035,35 asyncio DEBUG Using selector: KqueueSelector
2020-11-14 20:34:17,301,301 django.request ERROR Internal Server Error: /admin/view/survey/dashboard/
Traceback (most recent call last):
  File "/Users/mhope/Documents/projects/beta-survey-django/env/lib/python3.8/site-packages/pandas/core/indexes/base.py", line 2895, in get_loc
    return self._engine.get_loc(casted_key)
  File "pandas/_libs/index.pyx", line 70, in pandas._libs.index.IndexEngine.get_loc
  File "pandas/_libs/index.pyx", line 101, in pandas._libs.index.IndexEngine.get_loc
  File "pandas/_libs/hashtable_class_helper.pxi", line 1675, in pandas._libs.hashtable.PyObjectHashTable.get_item
  File "pandas/_libs/hashtable_class_helper.pxi", line 1683, in pandas._libs.hashtable.PyObjectHashTable.get_item
KeyError: 'age'

The above exception was the direct cause of the following exception:

Traceback (most recent call last):
  File "/Users/mhope/Documents/projects/beta-survey-django/env/lib/python3.8/site-packages/django/core/handlers/exception.py", line 47, in inner
    response = get_response(request)
  File "/Users/mhope/Documents/projects/beta-survey-django/env/lib/python3.8/site-packages/django/core/handlers/base.py", line 179, in _get_response
    response = wrapped_callback(request, *callback_args, **callback_kwargs)
  File "/Users/mhope/Documents/projects/beta-survey-django/env/lib/python3.8/site-packages/django/contrib/auth/decorators.py", line 21, in _wrapped_view
    return view_func(request, *args, **kwargs)
  File "/Users/mhope/Documents/projects/beta-survey-django/beta-survey-django/user_app/views.py", line 69, in dashboard
    (df['age'] < 18),
  File "/Users/mhope/Documents/projects/beta-survey-django/env/lib/python3.8/site-packages/pandas/core/frame.py", line 2906, in __getitem__
    indexer = self.columns.get_loc(key)
  File "/Users/mhope/Documents/projects/beta-survey-django/env/lib/python3.8/site-packages/pandas/core/indexes/base.py", line 2897, in get_loc
    raise KeyError(key) from err
KeyError: 'age'
2020-11-14 20:35:19,621,621 django.request ERROR Internal Server Error: /admin/view/survey/dashboard/
Traceback (most recent call last):
  File "/Users/mhope/Documents/projects/beta-survey-django/env/lib/python3.8/site-packages/pandas/core/indexes/base.py", line 2895, in get_loc
    return self._engine.get_loc(casted_key)
  File "pandas/_libs/index.pyx", line 70, in pandas._libs.index.IndexEngine.get_loc
  File "pandas/_libs/index.pyx", line 101, in pandas._libs.index.IndexEngine.get_loc
  File "pandas/_libs/hashtable_class_helper.pxi", line 1675, in pandas._libs.hashtable.PyObjectHashTable.get_item
  File "pandas/_libs/hashtable_class_helper.pxi", line 1683, in pandas._libs.hashtable.PyObjectHashTable.get_item
KeyError: 'age'

The above exception was the direct cause of the following exception:

Traceback (most recent call last):
  File "/Users/mhope/Documents/projects/beta-survey-django/env/lib/python3.8/site-packages/django/core/handlers/exception.py", line 47, in inner
    response = get_response(request)
  File "/Users/mhope/Documents/projects/beta-survey-django/env/lib/python3.8/site-packages/django/core/handlers/base.py", line 179, in _get_response
    response = wrapped_callback(request, *callback_args, **callback_kwargs)
  File "/Users/mhope/Documents/projects/beta-survey-django/env/lib/python3.8/site-packages/django/contrib/auth/decorators.py", line 21, in _wrapped_view
    return view_func(request, *args, **kwargs)
  File "/Users/mhope/Documents/projects/beta-survey-django/beta-survey-django/user_app/views.py", line 69, in dashboard
    (df['age'] < 18),
  File "/Users/mhope/Documents/projects/beta-survey-django/env/lib/python3.8/site-packages/pandas/core/frame.py", line 2906, in __getitem__
    indexer = self.columns.get_loc(key)
  File "/Users/mhope/Documents/projects/beta-survey-django/env/lib/python3.8/site-packages/pandas/core/indexes/base.py", line 2897, in get_loc
    raise KeyError(key) from err
KeyError: 'age'
2020-11-14 20:35:54,939,939 asyncio DEBUG Using selector: KqueueSelector
2020-11-14 20:41:15,824,824 asyncio DEBUG Using selector: KqueueSelector
2020-11-14 20:42:23,150,150 asyncio DEBUG Using selector: KqueueSelector
2020-11-14 20:42:35,965,965 asyncio DEBUG Using selector: KqueueSelector
2020-11-14 20:43:30,648,648 django.request WARNING Not Found: /favicon.ico
2020-11-14 20:43:35,411,411 asyncio DEBUG Using selector: KqueueSelector
2020-11-14 20:43:44,210,210 asyncio DEBUG Using selector: KqueueSelector
2020-11-14 20:44:39,346,346 asyncio DEBUG Using selector: KqueueSelector
2020-11-14 20:53:09,187,187 urllib3.connectionpool DEBUG Starting new HTTPS connection (1): ipleak.net:443
2020-11-14 20:53:09,291,291 django.request ERROR Internal Server Error: /
Traceback (most recent call last):
  File "/Users/mhope/Documents/projects/beta-survey-django/env/lib/python3.8/site-packages/urllib3/connection.py", line 159, in _new_conn
    conn = connection.create_connection(
  File "/Users/mhope/Documents/projects/beta-survey-django/env/lib/python3.8/site-packages/urllib3/util/connection.py", line 61, in create_connection
    for res in socket.getaddrinfo(host, port, family, socket.SOCK_STREAM):
  File "/Library/Developer/CommandLineTools/Library/Frameworks/Python3.framework/Versions/3.8/lib/python3.8/socket.py", line 918, in getaddrinfo
    for res in _socket.getaddrinfo(host, port, family, type, proto, flags):
socket.gaierror: [Errno 8] nodename nor servname provided, or not known

During handling of the above exception, another exception occurred:

Traceback (most recent call last):
  File "/Users/mhope/Documents/projects/beta-survey-django/env/lib/python3.8/site-packages/urllib3/connectionpool.py", line 670, in urlopen
    httplib_response = self._make_request(
  File "/Users/mhope/Documents/projects/beta-survey-django/env/lib/python3.8/site-packages/urllib3/connectionpool.py", line 381, in _make_request
    self._validate_conn(conn)
  File "/Users/mhope/Documents/projects/beta-survey-django/env/lib/python3.8/site-packages/urllib3/connectionpool.py", line 978, in _validate_conn
    conn.connect()
  File "/Users/mhope/Documents/projects/beta-survey-django/env/lib/python3.8/site-packages/urllib3/connection.py", line 309, in connect
    conn = self._new_conn()
  File "/Users/mhope/Documents/projects/beta-survey-django/env/lib/python3.8/site-packages/urllib3/connection.py", line 171, in _new_conn
    raise NewConnectionError(
urllib3.exceptions.NewConnectionError: <urllib3.connection.HTTPSConnection object at 0x11c20ddc0>: Failed to establish a new connection: [Errno 8] nodename nor servname provided, or not known

During handling of the above exception, another exception occurred:

Traceback (most recent call last):
  File "/Users/mhope/Documents/projects/beta-survey-django/env/lib/python3.8/site-packages/requests/adapters.py", line 439, in send
    resp = conn.urlopen(
  File "/Users/mhope/Documents/projects/beta-survey-django/env/lib/python3.8/site-packages/urllib3/connectionpool.py", line 726, in urlopen
    retries = retries.increment(
  File "/Users/mhope/Documents/projects/beta-survey-django/env/lib/python3.8/site-packages/urllib3/util/retry.py", line 446, in increment
    raise MaxRetryError(_pool, url, error or ResponseError(cause))
urllib3.exceptions.MaxRetryError: HTTPSConnectionPool(host='ipleak.net', port=443): Max retries exceeded with url: /json/ (Caused by NewConnectionError('<urllib3.connection.HTTPSConnection object at 0x11c20ddc0>: Failed to establish a new connection: [Errno 8] nodename nor servname provided, or not known'))

During handling of the above exception, another exception occurred:

Traceback (most recent call last):
  File "/Users/mhope/Documents/projects/beta-survey-django/env/lib/python3.8/site-packages/django/core/handlers/exception.py", line 47, in inner
    response = get_response(request)
  File "/Users/mhope/Documents/projects/beta-survey-django/env/lib/python3.8/site-packages/django/core/handlers/base.py", line 179, in _get_response
    response = wrapped_callback(request, *callback_args, **callback_kwargs)
  File "/Users/mhope/Documents/projects/beta-survey-django/beta-survey-django/beta_survey_django/views.py", line 48, in index
    location_request = requests.get(url = url, headers = headers)
  File "/Users/mhope/Documents/projects/beta-survey-django/env/lib/python3.8/site-packages/requests/api.py", line 76, in get
    return request('get', url, params=params, **kwargs)
  File "/Users/mhope/Documents/projects/beta-survey-django/env/lib/python3.8/site-packages/requests/api.py", line 61, in request
    return session.request(method=method, url=url, **kwargs)
  File "/Users/mhope/Documents/projects/beta-survey-django/env/lib/python3.8/site-packages/requests/sessions.py", line 530, in request
    resp = self.send(prep, **send_kwargs)
  File "/Users/mhope/Documents/projects/beta-survey-django/env/lib/python3.8/site-packages/requests/sessions.py", line 643, in send
    r = adapter.send(request, **kwargs)
  File "/Users/mhope/Documents/projects/beta-survey-django/env/lib/python3.8/site-packages/requests/adapters.py", line 516, in send
    raise ConnectionError(e, request=request)
requests.exceptions.ConnectionError: HTTPSConnectionPool(host='ipleak.net', port=443): Max retries exceeded with url: /json/ (Caused by NewConnectionError('<urllib3.connection.HTTPSConnection object at 0x11c20ddc0>: Failed to establish a new connection: [Errno 8] nodename nor servname provided, or not known'))
2020-11-14 20:53:15,323,323 asyncio DEBUG Using selector: KqueueSelector
2020-11-14 20:53:43,326,326 urllib3.connectionpool DEBUG Starting new HTTPS connection (1): ipleak.net:443
2020-11-14 20:53:43,445,445 django.request ERROR Internal Server Error: /
Traceback (most recent call last):
  File "/Users/mhope/Documents/projects/beta-survey-django/env/lib/python3.8/site-packages/urllib3/connection.py", line 159, in _new_conn
    conn = connection.create_connection(
  File "/Users/mhope/Documents/projects/beta-survey-django/env/lib/python3.8/site-packages/urllib3/util/connection.py", line 61, in create_connection
    for res in socket.getaddrinfo(host, port, family, socket.SOCK_STREAM):
  File "/Library/Developer/CommandLineTools/Library/Frameworks/Python3.framework/Versions/3.8/lib/python3.8/socket.py", line 918, in getaddrinfo
    for res in _socket.getaddrinfo(host, port, family, type, proto, flags):
socket.gaierror: [Errno 8] nodename nor servname provided, or not known

During handling of the above exception, another exception occurred:

Traceback (most recent call last):
  File "/Users/mhope/Documents/projects/beta-survey-django/env/lib/python3.8/site-packages/urllib3/connectionpool.py", line 670, in urlopen
    httplib_response = self._make_request(
  File "/Users/mhope/Documents/projects/beta-survey-django/env/lib/python3.8/site-packages/urllib3/connectionpool.py", line 381, in _make_request
    self._validate_conn(conn)
  File "/Users/mhope/Documents/projects/beta-survey-django/env/lib/python3.8/site-packages/urllib3/connectionpool.py", line 978, in _validate_conn
    conn.connect()
  File "/Users/mhope/Documents/projects/beta-survey-django/env/lib/python3.8/site-packages/urllib3/connection.py", line 309, in connect
    conn = self._new_conn()
  File "/Users/mhope/Documents/projects/beta-survey-django/env/lib/python3.8/site-packages/urllib3/connection.py", line 171, in _new_conn
    raise NewConnectionError(
urllib3.exceptions.NewConnectionError: <urllib3.connection.HTTPSConnection object at 0x1185519a0>: Failed to establish a new connection: [Errno 8] nodename nor servname provided, or not known

During handling of the above exception, another exception occurred:

Traceback (most recent call last):
  File "/Users/mhope/Documents/projects/beta-survey-django/env/lib/python3.8/site-packages/requests/adapters.py", line 439, in send
    resp = conn.urlopen(
  File "/Users/mhope/Documents/projects/beta-survey-django/env/lib/python3.8/site-packages/urllib3/connectionpool.py", line 726, in urlopen
    retries = retries.increment(
  File "/Users/mhope/Documents/projects/beta-survey-django/env/lib/python3.8/site-packages/urllib3/util/retry.py", line 446, in increment
    raise MaxRetryError(_pool, url, error or ResponseError(cause))
urllib3.exceptions.MaxRetryError: HTTPSConnectionPool(host='ipleak.net', port=443): Max retries exceeded with url: /json/ (Caused by NewConnectionError('<urllib3.connection.HTTPSConnection object at 0x1185519a0>: Failed to establish a new connection: [Errno 8] nodename nor servname provided, or not known'))

During handling of the above exception, another exception occurred:

Traceback (most recent call last):
  File "/Users/mhope/Documents/projects/beta-survey-django/env/lib/python3.8/site-packages/django/core/handlers/exception.py", line 47, in inner
    response = get_response(request)
  File "/Users/mhope/Documents/projects/beta-survey-django/env/lib/python3.8/site-packages/django/core/handlers/base.py", line 179, in _get_response
    response = wrapped_callback(request, *callback_args, **callback_kwargs)
  File "/Users/mhope/Documents/projects/beta-survey-django/beta-survey-django/beta_survey_django/views.py", line 48, in index
    location_request = requests.get(url = url, headers = headers)
  File "/Users/mhope/Documents/projects/beta-survey-django/env/lib/python3.8/site-packages/requests/api.py", line 76, in get
    return request('get', url, params=params, **kwargs)
  File "/Users/mhope/Documents/projects/beta-survey-django/env/lib/python3.8/site-packages/requests/api.py", line 61, in request
    return session.request(method=method, url=url, **kwargs)
  File "/Users/mhope/Documents/projects/beta-survey-django/env/lib/python3.8/site-packages/requests/sessions.py", line 530, in request
    resp = self.send(prep, **send_kwargs)
  File "/Users/mhope/Documents/projects/beta-survey-django/env/lib/python3.8/site-packages/requests/sessions.py", line 643, in send
    r = adapter.send(request, **kwargs)
  File "/Users/mhope/Documents/projects/beta-survey-django/env/lib/python3.8/site-packages/requests/adapters.py", line 516, in send
    raise ConnectionError(e, request=request)
requests.exceptions.ConnectionError: HTTPSConnectionPool(host='ipleak.net', port=443): Max retries exceeded with url: /json/ (Caused by NewConnectionError('<urllib3.connection.HTTPSConnection object at 0x1185519a0>: Failed to establish a new connection: [Errno 8] nodename nor servname provided, or not known'))
2020-11-14 20:53:47,019,19 urllib3.connectionpool DEBUG Starting new HTTPS connection (1): ipleak.net:443
2020-11-14 20:53:47,092,92 django.request ERROR Internal Server Error: /
Traceback (most recent call last):
  File "/Users/mhope/Documents/projects/beta-survey-django/env/lib/python3.8/site-packages/urllib3/connection.py", line 159, in _new_conn
    conn = connection.create_connection(
  File "/Users/mhope/Documents/projects/beta-survey-django/env/lib/python3.8/site-packages/urllib3/util/connection.py", line 61, in create_connection
    for res in socket.getaddrinfo(host, port, family, socket.SOCK_STREAM):
  File "/Library/Developer/CommandLineTools/Library/Frameworks/Python3.framework/Versions/3.8/lib/python3.8/socket.py", line 918, in getaddrinfo
    for res in _socket.getaddrinfo(host, port, family, type, proto, flags):
socket.gaierror: [Errno 8] nodename nor servname provided, or not known

During handling of the above exception, another exception occurred:

Traceback (most recent call last):
  File "/Users/mhope/Documents/projects/beta-survey-django/env/lib/python3.8/site-packages/urllib3/connectionpool.py", line 670, in urlopen
    httplib_response = self._make_request(
  File "/Users/mhope/Documents/projects/beta-survey-django/env/lib/python3.8/site-packages/urllib3/connectionpool.py", line 381, in _make_request
    self._validate_conn(conn)
  File "/Users/mhope/Documents/projects/beta-survey-django/env/lib/python3.8/site-packages/urllib3/connectionpool.py", line 978, in _validate_conn
    conn.connect()
  File "/Users/mhope/Documents/projects/beta-survey-django/env/lib/python3.8/site-packages/urllib3/connection.py", line 309, in connect
    conn = self._new_conn()
  File "/Users/mhope/Documents/projects/beta-survey-django/env/lib/python3.8/site-packages/urllib3/connection.py", line 171, in _new_conn
    raise NewConnectionError(
urllib3.exceptions.NewConnectionError: <urllib3.connection.HTTPSConnection object at 0x1184853a0>: Failed to establish a new connection: [Errno 8] nodename nor servname provided, or not known

During handling of the above exception, another exception occurred:

Traceback (most recent call last):
  File "/Users/mhope/Documents/projects/beta-survey-django/env/lib/python3.8/site-packages/requests/adapters.py", line 439, in send
    resp = conn.urlopen(
  File "/Users/mhope/Documents/projects/beta-survey-django/env/lib/python3.8/site-packages/urllib3/connectionpool.py", line 726, in urlopen
    retries = retries.increment(
  File "/Users/mhope/Documents/projects/beta-survey-django/env/lib/python3.8/site-packages/urllib3/util/retry.py", line 446, in increment
    raise MaxRetryError(_pool, url, error or ResponseError(cause))
urllib3.exceptions.MaxRetryError: HTTPSConnectionPool(host='ipleak.net', port=443): Max retries exceeded with url: /json/ (Caused by NewConnectionError('<urllib3.connection.HTTPSConnection object at 0x1184853a0>: Failed to establish a new connection: [Errno 8] nodename nor servname provided, or not known'))

During handling of the above exception, another exception occurred:

Traceback (most recent call last):
  File "/Users/mhope/Documents/projects/beta-survey-django/env/lib/python3.8/site-packages/django/core/handlers/exception.py", line 47, in inner
    response = get_response(request)
  File "/Users/mhope/Documents/projects/beta-survey-django/env/lib/python3.8/site-packages/django/core/handlers/base.py", line 179, in _get_response
    response = wrapped_callback(request, *callback_args, **callback_kwargs)
  File "/Users/mhope/Documents/projects/beta-survey-django/beta-survey-django/beta_survey_django/views.py", line 48, in index
    location_request = requests.get(url = url, headers = headers)
  File "/Users/mhope/Documents/projects/beta-survey-django/env/lib/python3.8/site-packages/requests/api.py", line 76, in get
    return request('get', url, params=params, **kwargs)
  File "/Users/mhope/Documents/projects/beta-survey-django/env/lib/python3.8/site-packages/requests/api.py", line 61, in request
    return session.request(method=method, url=url, **kwargs)
  File "/Users/mhope/Documents/projects/beta-survey-django/env/lib/python3.8/site-packages/requests/sessions.py", line 530, in request
    resp = self.send(prep, **send_kwargs)
  File "/Users/mhope/Documents/projects/beta-survey-django/env/lib/python3.8/site-packages/requests/sessions.py", line 643, in send
    r = adapter.send(request, **kwargs)
  File "/Users/mhope/Documents/projects/beta-survey-django/env/lib/python3.8/site-packages/requests/adapters.py", line 516, in send
    raise ConnectionError(e, request=request)
requests.exceptions.ConnectionError: HTTPSConnectionPool(host='ipleak.net', port=443): Max retries exceeded with url: /json/ (Caused by NewConnectionError('<urllib3.connection.HTTPSConnection object at 0x1184853a0>: Failed to establish a new connection: [Errno 8] nodename nor servname provided, or not known'))
2020-11-14 20:53:50,303,303 asyncio DEBUG Using selector: KqueueSelector
2020-11-14 20:54:11,405,405 urllib3.connectionpool DEBUG Starting new HTTPS connection (1): ipleak.net:443
2020-11-14 20:54:11,506,506 django.request ERROR Internal Server Error: /
Traceback (most recent call last):
  File "/Users/mhope/Documents/projects/beta-survey-django/env/lib/python3.8/site-packages/urllib3/connection.py", line 159, in _new_conn
    conn = connection.create_connection(
  File "/Users/mhope/Documents/projects/beta-survey-django/env/lib/python3.8/site-packages/urllib3/util/connection.py", line 61, in create_connection
    for res in socket.getaddrinfo(host, port, family, socket.SOCK_STREAM):
  File "/Library/Developer/CommandLineTools/Library/Frameworks/Python3.framework/Versions/3.8/lib/python3.8/socket.py", line 918, in getaddrinfo
    for res in _socket.getaddrinfo(host, port, family, type, proto, flags):
socket.gaierror: [Errno 8] nodename nor servname provided, or not known

During handling of the above exception, another exception occurred:

Traceback (most recent call last):
  File "/Users/mhope/Documents/projects/beta-survey-django/env/lib/python3.8/site-packages/urllib3/connectionpool.py", line 670, in urlopen
    httplib_response = self._make_request(
  File "/Users/mhope/Documents/projects/beta-survey-django/env/lib/python3.8/site-packages/urllib3/connectionpool.py", line 381, in _make_request
    self._validate_conn(conn)
  File "/Users/mhope/Documents/projects/beta-survey-django/env/lib/python3.8/site-packages/urllib3/connectionpool.py", line 978, in _validate_conn
    conn.connect()
  File "/Users/mhope/Documents/projects/beta-survey-django/env/lib/python3.8/site-packages/urllib3/connection.py", line 309, in connect
    conn = self._new_conn()
  File "/Users/mhope/Documents/projects/beta-survey-django/env/lib/python3.8/site-packages/urllib3/connection.py", line 171, in _new_conn
    raise NewConnectionError(
urllib3.exceptions.NewConnectionError: <urllib3.connection.HTTPSConnection object at 0x10f0b8ac0>: Failed to establish a new connection: [Errno 8] nodename nor servname provided, or not known

During handling of the above exception, another exception occurred:

Traceback (most recent call last):
  File "/Users/mhope/Documents/projects/beta-survey-django/env/lib/python3.8/site-packages/requests/adapters.py", line 439, in send
    resp = conn.urlopen(
  File "/Users/mhope/Documents/projects/beta-survey-django/env/lib/python3.8/site-packages/urllib3/connectionpool.py", line 726, in urlopen
    retries = retries.increment(
  File "/Users/mhope/Documents/projects/beta-survey-django/env/lib/python3.8/site-packages/urllib3/util/retry.py", line 446, in increment
    raise MaxRetryError(_pool, url, error or ResponseError(cause))
urllib3.exceptions.MaxRetryError: HTTPSConnectionPool(host='ipleak.net', port=443): Max retries exceeded with url: /json/ (Caused by NewConnectionError('<urllib3.connection.HTTPSConnection object at 0x10f0b8ac0>: Failed to establish a new connection: [Errno 8] nodename nor servname provided, or not known'))

During handling of the above exception, another exception occurred:

Traceback (most recent call last):
  File "/Users/mhope/Documents/projects/beta-survey-django/env/lib/python3.8/site-packages/django/core/handlers/exception.py", line 47, in inner
    response = get_response(request)
  File "/Users/mhope/Documents/projects/beta-survey-django/env/lib/python3.8/site-packages/django/core/handlers/base.py", line 179, in _get_response
    response = wrapped_callback(request, *callback_args, **callback_kwargs)
  File "/Users/mhope/Documents/projects/beta-survey-django/beta-survey-django/beta_survey_django/views.py", line 48, in index
    location_request = requests.get(url = url, headers = headers)
  File "/Users/mhope/Documents/projects/beta-survey-django/env/lib/python3.8/site-packages/requests/api.py", line 76, in get
    return request('get', url, params=params, **kwargs)
  File "/Users/mhope/Documents/projects/beta-survey-django/env/lib/python3.8/site-packages/requests/api.py", line 61, in request
    return session.request(method=method, url=url, **kwargs)
  File "/Users/mhope/Documents/projects/beta-survey-django/env/lib/python3.8/site-packages/requests/sessions.py", line 530, in request
    resp = self.send(prep, **send_kwargs)
  File "/Users/mhope/Documents/projects/beta-survey-django/env/lib/python3.8/site-packages/requests/sessions.py", line 643, in send
    r = adapter.send(request, **kwargs)
  File "/Users/mhope/Documents/projects/beta-survey-django/env/lib/python3.8/site-packages/requests/adapters.py", line 516, in send
    raise ConnectionError(e, request=request)
requests.exceptions.ConnectionError: HTTPSConnectionPool(host='ipleak.net', port=443): Max retries exceeded with url: /json/ (Caused by NewConnectionError('<urllib3.connection.HTTPSConnection object at 0x10f0b8ac0>: Failed to establish a new connection: [Errno 8] nodename nor servname provided, or not known'))
2020-11-14 20:54:30,124,124 urllib3.connectionpool DEBUG Starting new HTTPS connection (1): ipleak.net:443
2020-11-14 20:54:30,192,192 django.request ERROR Internal Server Error: /
Traceback (most recent call last):
  File "/Users/mhope/Documents/projects/beta-survey-django/env/lib/python3.8/site-packages/urllib3/connection.py", line 159, in _new_conn
    conn = connection.create_connection(
  File "/Users/mhope/Documents/projects/beta-survey-django/env/lib/python3.8/site-packages/urllib3/util/connection.py", line 61, in create_connection
    for res in socket.getaddrinfo(host, port, family, socket.SOCK_STREAM):
  File "/Library/Developer/CommandLineTools/Library/Frameworks/Python3.framework/Versions/3.8/lib/python3.8/socket.py", line 918, in getaddrinfo
    for res in _socket.getaddrinfo(host, port, family, type, proto, flags):
socket.gaierror: [Errno 8] nodename nor servname provided, or not known

During handling of the above exception, another exception occurred:

Traceback (most recent call last):
  File "/Users/mhope/Documents/projects/beta-survey-django/env/lib/python3.8/site-packages/urllib3/connectionpool.py", line 670, in urlopen
    httplib_response = self._make_request(
  File "/Users/mhope/Documents/projects/beta-survey-django/env/lib/python3.8/site-packages/urllib3/connectionpool.py", line 381, in _make_request
    self._validate_conn(conn)
  File "/Users/mhope/Documents/projects/beta-survey-django/env/lib/python3.8/site-packages/urllib3/connectionpool.py", line 978, in _validate_conn
    conn.connect()
  File "/Users/mhope/Documents/projects/beta-survey-django/env/lib/python3.8/site-packages/urllib3/connection.py", line 309, in connect
    conn = self._new_conn()
  File "/Users/mhope/Documents/projects/beta-survey-django/env/lib/python3.8/site-packages/urllib3/connection.py", line 171, in _new_conn
    raise NewConnectionError(
urllib3.exceptions.NewConnectionError: <urllib3.connection.HTTPSConnection object at 0x10f28c430>: Failed to establish a new connection: [Errno 8] nodename nor servname provided, or not known

During handling of the above exception, another exception occurred:

Traceback (most recent call last):
  File "/Users/mhope/Documents/projects/beta-survey-django/env/lib/python3.8/site-packages/requests/adapters.py", line 439, in send
    resp = conn.urlopen(
  File "/Users/mhope/Documents/projects/beta-survey-django/env/lib/python3.8/site-packages/urllib3/connectionpool.py", line 726, in urlopen
    retries = retries.increment(
  File "/Users/mhope/Documents/projects/beta-survey-django/env/lib/python3.8/site-packages/urllib3/util/retry.py", line 446, in increment
    raise MaxRetryError(_pool, url, error or ResponseError(cause))
urllib3.exceptions.MaxRetryError: HTTPSConnectionPool(host='ipleak.net', port=443): Max retries exceeded with url: /json/ (Caused by NewConnectionError('<urllib3.connection.HTTPSConnection object at 0x10f28c430>: Failed to establish a new connection: [Errno 8] nodename nor servname provided, or not known'))

During handling of the above exception, another exception occurred:

Traceback (most recent call last):
  File "/Users/mhope/Documents/projects/beta-survey-django/env/lib/python3.8/site-packages/django/core/handlers/exception.py", line 47, in inner
    response = get_response(request)
  File "/Users/mhope/Documents/projects/beta-survey-django/env/lib/python3.8/site-packages/django/core/handlers/base.py", line 179, in _get_response
    response = wrapped_callback(request, *callback_args, **callback_kwargs)
  File "/Users/mhope/Documents/projects/beta-survey-django/beta-survey-django/beta_survey_django/views.py", line 48, in index
    location_request = requests.get(url = url, headers = headers)
  File "/Users/mhope/Documents/projects/beta-survey-django/env/lib/python3.8/site-packages/requests/api.py", line 76, in get
    return request('get', url, params=params, **kwargs)
  File "/Users/mhope/Documents/projects/beta-survey-django/env/lib/python3.8/site-packages/requests/api.py", line 61, in request
    return session.request(method=method, url=url, **kwargs)
  File "/Users/mhope/Documents/projects/beta-survey-django/env/lib/python3.8/site-packages/requests/sessions.py", line 530, in request
    resp = self.send(prep, **send_kwargs)
  File "/Users/mhope/Documents/projects/beta-survey-django/env/lib/python3.8/site-packages/requests/sessions.py", line 643, in send
    r = adapter.send(request, **kwargs)
  File "/Users/mhope/Documents/projects/beta-survey-django/env/lib/python3.8/site-packages/requests/adapters.py", line 516, in send
    raise ConnectionError(e, request=request)
requests.exceptions.ConnectionError: HTTPSConnectionPool(host='ipleak.net', port=443): Max retries exceeded with url: /json/ (Caused by NewConnectionError('<urllib3.connection.HTTPSConnection object at 0x10f28c430>: Failed to establish a new connection: [Errno 8] nodename nor servname provided, or not known'))
2020-11-14 20:54:33,862,862 urllib3.connectionpool DEBUG Starting new HTTPS connection (1): ipleak.net:443
2020-11-14 20:54:33,933,933 django.request ERROR Internal Server Error: /
Traceback (most recent call last):
  File "/Users/mhope/Documents/projects/beta-survey-django/env/lib/python3.8/site-packages/urllib3/connection.py", line 159, in _new_conn
    conn = connection.create_connection(
  File "/Users/mhope/Documents/projects/beta-survey-django/env/lib/python3.8/site-packages/urllib3/util/connection.py", line 61, in create_connection
    for res in socket.getaddrinfo(host, port, family, socket.SOCK_STREAM):
  File "/Library/Developer/CommandLineTools/Library/Frameworks/Python3.framework/Versions/3.8/lib/python3.8/socket.py", line 918, in getaddrinfo
    for res in _socket.getaddrinfo(host, port, family, type, proto, flags):
socket.gaierror: [Errno 8] nodename nor servname provided, or not known

During handling of the above exception, another exception occurred:

Traceback (most recent call last):
  File "/Users/mhope/Documents/projects/beta-survey-django/env/lib/python3.8/site-packages/urllib3/connectionpool.py", line 670, in urlopen
    httplib_response = self._make_request(
  File "/Users/mhope/Documents/projects/beta-survey-django/env/lib/python3.8/site-packages/urllib3/connectionpool.py", line 381, in _make_request
    self._validate_conn(conn)
  File "/Users/mhope/Documents/projects/beta-survey-django/env/lib/python3.8/site-packages/urllib3/connectionpool.py", line 978, in _validate_conn
    conn.connect()
  File "/Users/mhope/Documents/projects/beta-survey-django/env/lib/python3.8/site-packages/urllib3/connection.py", line 309, in connect
    conn = self._new_conn()
  File "/Users/mhope/Documents/projects/beta-survey-django/env/lib/python3.8/site-packages/urllib3/connection.py", line 171, in _new_conn
    raise NewConnectionError(
urllib3.exceptions.NewConnectionError: <urllib3.connection.HTTPSConnection object at 0x10f275b20>: Failed to establish a new connection: [Errno 8] nodename nor servname provided, or not known

During handling of the above exception, another exception occurred:

Traceback (most recent call last):
  File "/Users/mhope/Documents/projects/beta-survey-django/env/lib/python3.8/site-packages/requests/adapters.py", line 439, in send
    resp = conn.urlopen(
  File "/Users/mhope/Documents/projects/beta-survey-django/env/lib/python3.8/site-packages/urllib3/connectionpool.py", line 726, in urlopen
    retries = retries.increment(
  File "/Users/mhope/Documents/projects/beta-survey-django/env/lib/python3.8/site-packages/urllib3/util/retry.py", line 446, in increment
    raise MaxRetryError(_pool, url, error or ResponseError(cause))
urllib3.exceptions.MaxRetryError: HTTPSConnectionPool(host='ipleak.net', port=443): Max retries exceeded with url: /json/ (Caused by NewConnectionError('<urllib3.connection.HTTPSConnection object at 0x10f275b20>: Failed to establish a new connection: [Errno 8] nodename nor servname provided, or not known'))

During handling of the above exception, another exception occurred:

Traceback (most recent call last):
  File "/Users/mhope/Documents/projects/beta-survey-django/env/lib/python3.8/site-packages/django/core/handlers/exception.py", line 47, in inner
    response = get_response(request)
  File "/Users/mhope/Documents/projects/beta-survey-django/env/lib/python3.8/site-packages/django/core/handlers/base.py", line 179, in _get_response
    response = wrapped_callback(request, *callback_args, **callback_kwargs)
  File "/Users/mhope/Documents/projects/beta-survey-django/beta-survey-django/beta_survey_django/views.py", line 48, in index
    location_request = requests.get(url = url, headers = headers)
  File "/Users/mhope/Documents/projects/beta-survey-django/env/lib/python3.8/site-packages/requests/api.py", line 76, in get
    return request('get', url, params=params, **kwargs)
  File "/Users/mhope/Documents/projects/beta-survey-django/env/lib/python3.8/site-packages/requests/api.py", line 61, in request
    return session.request(method=method, url=url, **kwargs)
  File "/Users/mhope/Documents/projects/beta-survey-django/env/lib/python3.8/site-packages/requests/sessions.py", line 530, in request
    resp = self.send(prep, **send_kwargs)
  File "/Users/mhope/Documents/projects/beta-survey-django/env/lib/python3.8/site-packages/requests/sessions.py", line 643, in send
    r = adapter.send(request, **kwargs)
  File "/Users/mhope/Documents/projects/beta-survey-django/env/lib/python3.8/site-packages/requests/adapters.py", line 516, in send
    raise ConnectionError(e, request=request)
requests.exceptions.ConnectionError: HTTPSConnectionPool(host='ipleak.net', port=443): Max retries exceeded with url: /json/ (Caused by NewConnectionError('<urllib3.connection.HTTPSConnection object at 0x10f275b20>: Failed to establish a new connection: [Errno 8] nodename nor servname provided, or not known'))
2020-11-14 20:54:43,962,962 asyncio DEBUG Using selector: KqueueSelector
2020-11-14 20:54:53,062,62 urllib3.connectionpool DEBUG Starting new HTTPS connection (1): ipleak.net:443
2020-11-14 20:54:53,161,161 django.request ERROR Internal Server Error: /
Traceback (most recent call last):
  File "/Users/mhope/Documents/projects/beta-survey-django/env/lib/python3.8/site-packages/urllib3/connection.py", line 159, in _new_conn
    conn = connection.create_connection(
  File "/Users/mhope/Documents/projects/beta-survey-django/env/lib/python3.8/site-packages/urllib3/util/connection.py", line 61, in create_connection
    for res in socket.getaddrinfo(host, port, family, socket.SOCK_STREAM):
  File "/Library/Developer/CommandLineTools/Library/Frameworks/Python3.framework/Versions/3.8/lib/python3.8/socket.py", line 918, in getaddrinfo
    for res in _socket.getaddrinfo(host, port, family, type, proto, flags):
socket.gaierror: [Errno 8] nodename nor servname provided, or not known

During handling of the above exception, another exception occurred:

Traceback (most recent call last):
  File "/Users/mhope/Documents/projects/beta-survey-django/env/lib/python3.8/site-packages/urllib3/connectionpool.py", line 670, in urlopen
    httplib_response = self._make_request(
  File "/Users/mhope/Documents/projects/beta-survey-django/env/lib/python3.8/site-packages/urllib3/connectionpool.py", line 381, in _make_request
    self._validate_conn(conn)
  File "/Users/mhope/Documents/projects/beta-survey-django/env/lib/python3.8/site-packages/urllib3/connectionpool.py", line 978, in _validate_conn
    conn.connect()
  File "/Users/mhope/Documents/projects/beta-survey-django/env/lib/python3.8/site-packages/urllib3/connection.py", line 309, in connect
    conn = self._new_conn()
  File "/Users/mhope/Documents/projects/beta-survey-django/env/lib/python3.8/site-packages/urllib3/connection.py", line 171, in _new_conn
    raise NewConnectionError(
urllib3.exceptions.NewConnectionError: <urllib3.connection.HTTPSConnection object at 0x11389b700>: Failed to establish a new connection: [Errno 8] nodename nor servname provided, or not known

During handling of the above exception, another exception occurred:

Traceback (most recent call last):
  File "/Users/mhope/Documents/projects/beta-survey-django/env/lib/python3.8/site-packages/requests/adapters.py", line 439, in send
    resp = conn.urlopen(
  File "/Users/mhope/Documents/projects/beta-survey-django/env/lib/python3.8/site-packages/urllib3/connectionpool.py", line 726, in urlopen
    retries = retries.increment(
  File "/Users/mhope/Documents/projects/beta-survey-django/env/lib/python3.8/site-packages/urllib3/util/retry.py", line 446, in increment
    raise MaxRetryError(_pool, url, error or ResponseError(cause))
urllib3.exceptions.MaxRetryError: HTTPSConnectionPool(host='ipleak.net', port=443): Max retries exceeded with url: /json/ (Caused by NewConnectionError('<urllib3.connection.HTTPSConnection object at 0x11389b700>: Failed to establish a new connection: [Errno 8] nodename nor servname provided, or not known'))

During handling of the above exception, another exception occurred:

Traceback (most recent call last):
  File "/Users/mhope/Documents/projects/beta-survey-django/env/lib/python3.8/site-packages/django/core/handlers/exception.py", line 47, in inner
    response = get_response(request)
  File "/Users/mhope/Documents/projects/beta-survey-django/env/lib/python3.8/site-packages/django/core/handlers/base.py", line 179, in _get_response
    response = wrapped_callback(request, *callback_args, **callback_kwargs)
  File "/Users/mhope/Documents/projects/beta-survey-django/beta-survey-django/beta_survey_django/views.py", line 48, in index
    location_request = requests.get(url = url, headers = headers)
  File "/Users/mhope/Documents/projects/beta-survey-django/env/lib/python3.8/site-packages/requests/api.py", line 76, in get
    return request('get', url, params=params, **kwargs)
  File "/Users/mhope/Documents/projects/beta-survey-django/env/lib/python3.8/site-packages/requests/api.py", line 61, in request
    return session.request(method=method, url=url, **kwargs)
  File "/Users/mhope/Documents/projects/beta-survey-django/env/lib/python3.8/site-packages/requests/sessions.py", line 530, in request
    resp = self.send(prep, **send_kwargs)
  File "/Users/mhope/Documents/projects/beta-survey-django/env/lib/python3.8/site-packages/requests/sessions.py", line 643, in send
    r = adapter.send(request, **kwargs)
  File "/Users/mhope/Documents/projects/beta-survey-django/env/lib/python3.8/site-packages/requests/adapters.py", line 516, in send
    raise ConnectionError(e, request=request)
requests.exceptions.ConnectionError: HTTPSConnectionPool(host='ipleak.net', port=443): Max retries exceeded with url: /json/ (Caused by NewConnectionError('<urllib3.connection.HTTPSConnection object at 0x11389b700>: Failed to establish a new connection: [Errno 8] nodename nor servname provided, or not known'))
2020-11-14 20:56:04,469,469 urllib3.connectionpool DEBUG Starting new HTTPS connection (1): ipleak.net:443
2020-11-14 20:56:05,532,532 django.request ERROR Internal Server Error: /
Traceback (most recent call last):
  File "/Users/mhope/Documents/projects/beta-survey-django/env/lib/python3.8/site-packages/urllib3/connection.py", line 159, in _new_conn
    conn = connection.create_connection(
  File "/Users/mhope/Documents/projects/beta-survey-django/env/lib/python3.8/site-packages/urllib3/util/connection.py", line 61, in create_connection
    for res in socket.getaddrinfo(host, port, family, socket.SOCK_STREAM):
  File "/Library/Developer/CommandLineTools/Library/Frameworks/Python3.framework/Versions/3.8/lib/python3.8/socket.py", line 918, in getaddrinfo
    for res in _socket.getaddrinfo(host, port, family, type, proto, flags):
socket.gaierror: [Errno 8] nodename nor servname provided, or not known

During handling of the above exception, another exception occurred:

Traceback (most recent call last):
  File "/Users/mhope/Documents/projects/beta-survey-django/env/lib/python3.8/site-packages/urllib3/connectionpool.py", line 670, in urlopen
    httplib_response = self._make_request(
  File "/Users/mhope/Documents/projects/beta-survey-django/env/lib/python3.8/site-packages/urllib3/connectionpool.py", line 381, in _make_request
    self._validate_conn(conn)
  File "/Users/mhope/Documents/projects/beta-survey-django/env/lib/python3.8/site-packages/urllib3/connectionpool.py", line 978, in _validate_conn
    conn.connect()
  File "/Users/mhope/Documents/projects/beta-survey-django/env/lib/python3.8/site-packages/urllib3/connection.py", line 309, in connect
    conn = self._new_conn()
  File "/Users/mhope/Documents/projects/beta-survey-django/env/lib/python3.8/site-packages/urllib3/connection.py", line 171, in _new_conn
    raise NewConnectionError(
urllib3.exceptions.NewConnectionError: <urllib3.connection.HTTPSConnection object at 0x1137a79d0>: Failed to establish a new connection: [Errno 8] nodename nor servname provided, or not known

During handling of the above exception, another exception occurred:

Traceback (most recent call last):
  File "/Users/mhope/Documents/projects/beta-survey-django/env/lib/python3.8/site-packages/requests/adapters.py", line 439, in send
    resp = conn.urlopen(
  File "/Users/mhope/Documents/projects/beta-survey-django/env/lib/python3.8/site-packages/urllib3/connectionpool.py", line 726, in urlopen
    retries = retries.increment(
  File "/Users/mhope/Documents/projects/beta-survey-django/env/lib/python3.8/site-packages/urllib3/util/retry.py", line 446, in increment
    raise MaxRetryError(_pool, url, error or ResponseError(cause))
urllib3.exceptions.MaxRetryError: HTTPSConnectionPool(host='ipleak.net', port=443): Max retries exceeded with url: /json/ (Caused by NewConnectionError('<urllib3.connection.HTTPSConnection object at 0x1137a79d0>: Failed to establish a new connection: [Errno 8] nodename nor servname provided, or not known'))

During handling of the above exception, another exception occurred:

Traceback (most recent call last):
  File "/Users/mhope/Documents/projects/beta-survey-django/env/lib/python3.8/site-packages/django/core/handlers/exception.py", line 47, in inner
    response = get_response(request)
  File "/Users/mhope/Documents/projects/beta-survey-django/env/lib/python3.8/site-packages/django/core/handlers/base.py", line 179, in _get_response
    response = wrapped_callback(request, *callback_args, **callback_kwargs)
  File "/Users/mhope/Documents/projects/beta-survey-django/beta-survey-django/beta_survey_django/views.py", line 48, in index
    location_request = requests.get(url = url, headers = headers)
  File "/Users/mhope/Documents/projects/beta-survey-django/env/lib/python3.8/site-packages/requests/api.py", line 76, in get
    return request('get', url, params=params, **kwargs)
  File "/Users/mhope/Documents/projects/beta-survey-django/env/lib/python3.8/site-packages/requests/api.py", line 61, in request
    return session.request(method=method, url=url, **kwargs)
  File "/Users/mhope/Documents/projects/beta-survey-django/env/lib/python3.8/site-packages/requests/sessions.py", line 530, in request
    resp = self.send(prep, **send_kwargs)
  File "/Users/mhope/Documents/projects/beta-survey-django/env/lib/python3.8/site-packages/requests/sessions.py", line 643, in send
    r = adapter.send(request, **kwargs)
  File "/Users/mhope/Documents/projects/beta-survey-django/env/lib/python3.8/site-packages/requests/adapters.py", line 516, in send
    raise ConnectionError(e, request=request)
requests.exceptions.ConnectionError: HTTPSConnectionPool(host='ipleak.net', port=443): Max retries exceeded with url: /json/ (Caused by NewConnectionError('<urllib3.connection.HTTPSConnection object at 0x1137a79d0>: Failed to establish a new connection: [Errno 8] nodename nor servname provided, or not known'))
2020-11-14 20:58:10,289,289 urllib3.connectionpool DEBUG Starting new HTTPS connection (1): ipleak.net:443
2020-11-14 20:58:29,431,431 urllib3.connectionpool DEBUG https://ipleak.net:443 "GET /json/ HTTP/1.1" 200 None
2020-11-14 20:58:42,367,367 urllib3.connectionpool DEBUG Starting new HTTPS connection (1): deywuro.com:443
2020-11-14 20:58:44,079,79 urllib3.connectionpool DEBUG https://deywuro.com:443 "GET /api/sms?username=sammy&password=suppORT_pass_0987&source=Test&destination=0556581928&message=Your+OTP+is+261830 HTTP/1.1" 200 None
2020-11-14 20:59:40,658,658 urllib3.connectionpool DEBUG Starting new HTTPS connection (1): ipleak.net:443
2020-11-14 20:59:55,687,687 asyncio DEBUG Using selector: KqueueSelector
2020-11-14 21:00:05,332,332 urllib3.connectionpool DEBUG Starting new HTTPS connection (1): ipleak.net:443
2020-11-14 21:00:40,041,41 asyncio DEBUG Using selector: KqueueSelector
2020-11-14 21:00:49,154,154 urllib3.connectionpool DEBUG Starting new HTTPS connection (1): ipleak.net:443
2020-11-14 21:02:01,982,982 django.request ERROR Internal Server Error: /
Traceback (most recent call last):
  File "/Users/mhope/Documents/projects/beta-survey-django/env/lib/python3.8/site-packages/urllib3/connectionpool.py", line 670, in urlopen
    httplib_response = self._make_request(
  File "/Users/mhope/Documents/projects/beta-survey-django/env/lib/python3.8/site-packages/urllib3/connectionpool.py", line 381, in _make_request
    self._validate_conn(conn)
  File "/Users/mhope/Documents/projects/beta-survey-django/env/lib/python3.8/site-packages/urllib3/connectionpool.py", line 978, in _validate_conn
    conn.connect()
  File "/Users/mhope/Documents/projects/beta-survey-django/env/lib/python3.8/site-packages/urllib3/connection.py", line 362, in connect
    self.sock = ssl_wrap_socket(
  File "/Users/mhope/Documents/projects/beta-survey-django/env/lib/python3.8/site-packages/urllib3/util/ssl_.py", line 386, in ssl_wrap_socket
    return context.wrap_socket(sock, server_hostname=server_hostname)
  File "/Library/Developer/CommandLineTools/Library/Frameworks/Python3.framework/Versions/3.8/lib/python3.8/ssl.py", line 500, in wrap_socket
    return self.sslsocket_class._create(
  File "/Library/Developer/CommandLineTools/Library/Frameworks/Python3.framework/Versions/3.8/lib/python3.8/ssl.py", line 1040, in _create
    self.do_handshake()
  File "/Library/Developer/CommandLineTools/Library/Frameworks/Python3.framework/Versions/3.8/lib/python3.8/ssl.py", line 1309, in do_handshake
    self._sslobj.do_handshake()
ssl.SSLEOFError: EOF occurred in violation of protocol (_ssl.c:1108)

During handling of the above exception, another exception occurred:

Traceback (most recent call last):
  File "/Users/mhope/Documents/projects/beta-survey-django/env/lib/python3.8/site-packages/requests/adapters.py", line 439, in send
    resp = conn.urlopen(
  File "/Users/mhope/Documents/projects/beta-survey-django/env/lib/python3.8/site-packages/urllib3/connectionpool.py", line 726, in urlopen
    retries = retries.increment(
  File "/Users/mhope/Documents/projects/beta-survey-django/env/lib/python3.8/site-packages/urllib3/util/retry.py", line 446, in increment
    raise MaxRetryError(_pool, url, error or ResponseError(cause))
urllib3.exceptions.MaxRetryError: HTTPSConnectionPool(host='ipleak.net', port=443): Max retries exceeded with url: /json/ (Caused by SSLError(SSLEOFError(8, 'EOF occurred in violation of protocol (_ssl.c:1108)')))

During handling of the above exception, another exception occurred:

Traceback (most recent call last):
  File "/Users/mhope/Documents/projects/beta-survey-django/env/lib/python3.8/site-packages/django/core/handlers/exception.py", line 47, in inner
    response = get_response(request)
  File "/Users/mhope/Documents/projects/beta-survey-django/env/lib/python3.8/site-packages/django/core/handlers/base.py", line 179, in _get_response
    response = wrapped_callback(request, *callback_args, **callback_kwargs)
  File "/Users/mhope/Documents/projects/beta-survey-django/beta-survey-django/beta_survey_django/views.py", line 48, in index
    location_request = requests.get(url = url, headers = headers)
  File "/Users/mhope/Documents/projects/beta-survey-django/env/lib/python3.8/site-packages/requests/api.py", line 76, in get
    return request('get', url, params=params, **kwargs)
  File "/Users/mhope/Documents/projects/beta-survey-django/env/lib/python3.8/site-packages/requests/api.py", line 61, in request
    return session.request(method=method, url=url, **kwargs)
  File "/Users/mhope/Documents/projects/beta-survey-django/env/lib/python3.8/site-packages/requests/sessions.py", line 530, in request
    resp = self.send(prep, **send_kwargs)
  File "/Users/mhope/Documents/projects/beta-survey-django/env/lib/python3.8/site-packages/requests/sessions.py", line 643, in send
    r = adapter.send(request, **kwargs)
  File "/Users/mhope/Documents/projects/beta-survey-django/env/lib/python3.8/site-packages/requests/adapters.py", line 514, in send
    raise SSLError(e, request=request)
requests.exceptions.SSLError: HTTPSConnectionPool(host='ipleak.net', port=443): Max retries exceeded with url: /json/ (Caused by SSLError(SSLEOFError(8, 'EOF occurred in violation of protocol (_ssl.c:1108)')))
2020-11-14 21:02:06,679,679 asyncio DEBUG Using selector: KqueueSelector
2020-11-14 21:02:23,286,286 urllib3.connectionpool DEBUG Starting new HTTPS connection (1): ipleak.net:443
2020-11-14 21:03:00,390,390 django.request WARNING Not Found: /admin/l
2020-11-14 21:03:24,452,452 urllib3.connectionpool DEBUG Starting new HTTPS connection (1): ipleak.net:443
2020-11-14 21:03:38,577,577 django.request ERROR Internal Server Error: /
Traceback (most recent call last):
  File "/Users/mhope/Documents/projects/beta-survey-django/env/lib/python3.8/site-packages/urllib3/connection.py", line 159, in _new_conn
    conn = connection.create_connection(
  File "/Users/mhope/Documents/projects/beta-survey-django/env/lib/python3.8/site-packages/urllib3/util/connection.py", line 84, in create_connection
    raise err
  File "/Users/mhope/Documents/projects/beta-survey-django/env/lib/python3.8/site-packages/urllib3/util/connection.py", line 74, in create_connection
    sock.connect(sa)
TimeoutError: [Errno 60] Operation timed out

During handling of the above exception, another exception occurred:

Traceback (most recent call last):
  File "/Users/mhope/Documents/projects/beta-survey-django/env/lib/python3.8/site-packages/urllib3/connectionpool.py", line 670, in urlopen
    httplib_response = self._make_request(
  File "/Users/mhope/Documents/projects/beta-survey-django/env/lib/python3.8/site-packages/urllib3/connectionpool.py", line 381, in _make_request
    self._validate_conn(conn)
  File "/Users/mhope/Documents/projects/beta-survey-django/env/lib/python3.8/site-packages/urllib3/connectionpool.py", line 978, in _validate_conn
    conn.connect()
  File "/Users/mhope/Documents/projects/beta-survey-django/env/lib/python3.8/site-packages/urllib3/connection.py", line 309, in connect
    conn = self._new_conn()
  File "/Users/mhope/Documents/projects/beta-survey-django/env/lib/python3.8/site-packages/urllib3/connection.py", line 171, in _new_conn
    raise NewConnectionError(
urllib3.exceptions.NewConnectionError: <urllib3.connection.HTTPSConnection object at 0x11260f490>: Failed to establish a new connection: [Errno 60] Operation timed out

During handling of the above exception, another exception occurred:

Traceback (most recent call last):
  File "/Users/mhope/Documents/projects/beta-survey-django/env/lib/python3.8/site-packages/requests/adapters.py", line 439, in send
    resp = conn.urlopen(
  File "/Users/mhope/Documents/projects/beta-survey-django/env/lib/python3.8/site-packages/urllib3/connectionpool.py", line 726, in urlopen
    retries = retries.increment(
  File "/Users/mhope/Documents/projects/beta-survey-django/env/lib/python3.8/site-packages/urllib3/util/retry.py", line 446, in increment
    raise MaxRetryError(_pool, url, error or ResponseError(cause))
urllib3.exceptions.MaxRetryError: HTTPSConnectionPool(host='ipleak.net', port=443): Max retries exceeded with url: /json/ (Caused by NewConnectionError('<urllib3.connection.HTTPSConnection object at 0x11260f490>: Failed to establish a new connection: [Errno 60] Operation timed out'))

During handling of the above exception, another exception occurred:

Traceback (most recent call last):
  File "/Users/mhope/Documents/projects/beta-survey-django/env/lib/python3.8/site-packages/django/core/handlers/exception.py", line 47, in inner
    response = get_response(request)
  File "/Users/mhope/Documents/projects/beta-survey-django/env/lib/python3.8/site-packages/django/core/handlers/base.py", line 179, in _get_response
    response = wrapped_callback(request, *callback_args, **callback_kwargs)
  File "/Users/mhope/Documents/projects/beta-survey-django/beta-survey-django/beta_survey_django/views.py", line 48, in index
    location_request = requests.get(url = url, headers = headers)
  File "/Users/mhope/Documents/projects/beta-survey-django/env/lib/python3.8/site-packages/requests/api.py", line 76, in get
    return request('get', url, params=params, **kwargs)
  File "/Users/mhope/Documents/projects/beta-survey-django/env/lib/python3.8/site-packages/requests/api.py", line 61, in request
    return session.request(method=method, url=url, **kwargs)
  File "/Users/mhope/Documents/projects/beta-survey-django/env/lib/python3.8/site-packages/requests/sessions.py", line 530, in request
    resp = self.send(prep, **send_kwargs)
  File "/Users/mhope/Documents/projects/beta-survey-django/env/lib/python3.8/site-packages/requests/sessions.py", line 643, in send
    r = adapter.send(request, **kwargs)
  File "/Users/mhope/Documents/projects/beta-survey-django/env/lib/python3.8/site-packages/requests/adapters.py", line 516, in send
    raise ConnectionError(e, request=request)
requests.exceptions.ConnectionError: HTTPSConnectionPool(host='ipleak.net', port=443): Max retries exceeded with url: /json/ (Caused by NewConnectionError('<urllib3.connection.HTTPSConnection object at 0x11260f490>: Failed to establish a new connection: [Errno 60] Operation timed out'))
2020-11-14 21:04:08,337,337 asyncio DEBUG Using selector: KqueueSelector
2020-11-15 00:45:21,699,699 urllib3.connectionpool DEBUG Starting new HTTPS connection (1): ipleak.net:443
2020-11-15 00:45:30,688,688 urllib3.connectionpool DEBUG https://ipleak.net:443 "GET /json/ HTTP/1.1" 200 None
2020-11-15 00:45:53,636,636 urllib3.connectionpool DEBUG Starting new HTTPS connection (1): deywuro.com:443
2020-11-15 00:46:25,131,131 urllib3.connectionpool DEBUG https://deywuro.com:443 "GET /api/sms?username=sammy&password=suppORT_pass_0987&source=Test&destination=0556581928&message=Your+OTP+is+160061 HTTP/1.1" 200 None
2020-11-15 00:48:47,569,569 django.request ERROR Internal Server Error: /response
Traceback (most recent call last):
  File "/Users/mhope/Documents/projects/beta-survey-django/env/lib/python3.8/site-packages/rest_framework/serializers.py", line 939, in create
    instance = ModelClass._default_manager.create(**validated_data)
  File "/Users/mhope/Documents/projects/beta-survey-django/env/lib/python3.8/site-packages/django/db/models/manager.py", line 85, in manager_method
    return getattr(self.get_queryset(), name)(*args, **kwargs)
  File "/Users/mhope/Documents/projects/beta-survey-django/env/lib/python3.8/site-packages/django/db/models/query.py", line 445, in create
    obj = self.model(**kwargs)
  File "/Users/mhope/Documents/projects/beta-survey-django/env/lib/python3.8/site-packages/django/db/models/base.py", line 501, in __init__
    raise TypeError("%s() got an unexpected keyword argument '%s'" % (cls.__name__, kwarg))
TypeError: Responses() got an unexpected keyword argument 'belive_in_hand_washing'

During handling of the above exception, another exception occurred:

Traceback (most recent call last):
  File "/Users/mhope/Documents/projects/beta-survey-django/env/lib/python3.8/site-packages/django/core/handlers/exception.py", line 47, in inner
    response = get_response(request)
  File "/Users/mhope/Documents/projects/beta-survey-django/env/lib/python3.8/site-packages/django/core/handlers/base.py", line 179, in _get_response
    response = wrapped_callback(request, *callback_args, **callback_kwargs)
  File "/Users/mhope/Documents/projects/beta-survey-django/env/lib/python3.8/site-packages/django/views/decorators/csrf.py", line 54, in wrapped_view
    return view_func(*args, **kwargs)
  File "/Users/mhope/Documents/projects/beta-survey-django/env/lib/python3.8/site-packages/django/views/generic/base.py", line 70, in view
    return self.dispatch(request, *args, **kwargs)
  File "/Users/mhope/Documents/projects/beta-survey-django/env/lib/python3.8/site-packages/rest_framework/views.py", line 509, in dispatch
    response = self.handle_exception(exc)
  File "/Users/mhope/Documents/projects/beta-survey-django/env/lib/python3.8/site-packages/rest_framework/views.py", line 469, in handle_exception
    self.raise_uncaught_exception(exc)
  File "/Users/mhope/Documents/projects/beta-survey-django/env/lib/python3.8/site-packages/rest_framework/views.py", line 480, in raise_uncaught_exception
    raise exc
  File "/Users/mhope/Documents/projects/beta-survey-django/env/lib/python3.8/site-packages/rest_framework/views.py", line 506, in dispatch
    response = handler(request, *args, **kwargs)
  File "/Users/mhope/Documents/projects/beta-survey-django/env/lib/python3.8/site-packages/rest_framework/decorators.py", line 50, in handler
    return func(*args, **kwargs)
  File "/Users/mhope/Documents/projects/beta-survey-django/beta-survey-django/app/views.py", line 68, in response_api
    serializer.save()
  File "/Users/mhope/Documents/projects/beta-survey-django/env/lib/python3.8/site-packages/rest_framework/serializers.py", line 205, in save
    self.instance = self.create(validated_data)
  File "/Users/mhope/Documents/projects/beta-survey-django/env/lib/python3.8/site-packages/rest_framework/serializers.py", line 958, in create
    raise TypeError(msg)
TypeError: Got a `TypeError` when calling `Responses.objects.create()`. This may be because you have a writable field on the serializer class that is not a valid argument to `Responses.objects.create()`. You may need to make the field read-only, or override the ResponseSerializer.create() method to handle this correctly.
Original exception was:
 Traceback (most recent call last):
  File "/Users/mhope/Documents/projects/beta-survey-django/env/lib/python3.8/site-packages/rest_framework/serializers.py", line 939, in create
    instance = ModelClass._default_manager.create(**validated_data)
  File "/Users/mhope/Documents/projects/beta-survey-django/env/lib/python3.8/site-packages/django/db/models/manager.py", line 85, in manager_method
    return getattr(self.get_queryset(), name)(*args, **kwargs)
  File "/Users/mhope/Documents/projects/beta-survey-django/env/lib/python3.8/site-packages/django/db/models/query.py", line 445, in create
    obj = self.model(**kwargs)
  File "/Users/mhope/Documents/projects/beta-survey-django/env/lib/python3.8/site-packages/django/db/models/base.py", line 501, in __init__
    raise TypeError("%s() got an unexpected keyword argument '%s'" % (cls.__name__, kwarg))
TypeError: Responses() got an unexpected keyword argument 'belive_in_hand_washing'

2020-11-15 00:49:14,464,464 urllib3.connectionpool DEBUG Starting new HTTPS connection (1): ipleak.net:443
2020-11-15 00:49:53,113,113 urllib3.connectionpool DEBUG https://ipleak.net:443 "GET /json/ HTTP/1.1" 200 None
2020-11-15 00:50:55,106,106 django.request ERROR Internal Server Error: /response
Traceback (most recent call last):
  File "/Users/mhope/Documents/projects/beta-survey-django/env/lib/python3.8/site-packages/rest_framework/serializers.py", line 939, in create
    instance = ModelClass._default_manager.create(**validated_data)
  File "/Users/mhope/Documents/projects/beta-survey-django/env/lib/python3.8/site-packages/django/db/models/manager.py", line 85, in manager_method
    return getattr(self.get_queryset(), name)(*args, **kwargs)
  File "/Users/mhope/Documents/projects/beta-survey-django/env/lib/python3.8/site-packages/django/db/models/query.py", line 445, in create
    obj = self.model(**kwargs)
  File "/Users/mhope/Documents/projects/beta-survey-django/env/lib/python3.8/site-packages/django/db/models/base.py", line 501, in __init__
    raise TypeError("%s() got an unexpected keyword argument '%s'" % (cls.__name__, kwarg))
TypeError: Responses() got an unexpected keyword argument 'belive_in_hand_washing'

During handling of the above exception, another exception occurred:

Traceback (most recent call last):
  File "/Users/mhope/Documents/projects/beta-survey-django/env/lib/python3.8/site-packages/django/core/handlers/exception.py", line 47, in inner
    response = get_response(request)
  File "/Users/mhope/Documents/projects/beta-survey-django/env/lib/python3.8/site-packages/django/core/handlers/base.py", line 179, in _get_response
    response = wrapped_callback(request, *callback_args, **callback_kwargs)
  File "/Users/mhope/Documents/projects/beta-survey-django/env/lib/python3.8/site-packages/django/views/decorators/csrf.py", line 54, in wrapped_view
    return view_func(*args, **kwargs)
  File "/Users/mhope/Documents/projects/beta-survey-django/env/lib/python3.8/site-packages/django/views/generic/base.py", line 70, in view
    return self.dispatch(request, *args, **kwargs)
  File "/Users/mhope/Documents/projects/beta-survey-django/env/lib/python3.8/site-packages/rest_framework/views.py", line 509, in dispatch
    response = self.handle_exception(exc)
  File "/Users/mhope/Documents/projects/beta-survey-django/env/lib/python3.8/site-packages/rest_framework/views.py", line 469, in handle_exception
    self.raise_uncaught_exception(exc)
  File "/Users/mhope/Documents/projects/beta-survey-django/env/lib/python3.8/site-packages/rest_framework/views.py", line 480, in raise_uncaught_exception
    raise exc
  File "/Users/mhope/Documents/projects/beta-survey-django/env/lib/python3.8/site-packages/rest_framework/views.py", line 506, in dispatch
    response = handler(request, *args, **kwargs)
  File "/Users/mhope/Documents/projects/beta-survey-django/env/lib/python3.8/site-packages/rest_framework/decorators.py", line 50, in handler
    return func(*args, **kwargs)
  File "/Users/mhope/Documents/projects/beta-survey-django/beta-survey-django/app/views.py", line 68, in response_api
    serializer.save()
  File "/Users/mhope/Documents/projects/beta-survey-django/env/lib/python3.8/site-packages/rest_framework/serializers.py", line 205, in save
    self.instance = self.create(validated_data)
  File "/Users/mhope/Documents/projects/beta-survey-django/env/lib/python3.8/site-packages/rest_framework/serializers.py", line 958, in create
    raise TypeError(msg)
TypeError: Got a `TypeError` when calling `Responses.objects.create()`. This may be because you have a writable field on the serializer class that is not a valid argument to `Responses.objects.create()`. You may need to make the field read-only, or override the ResponseSerializer.create() method to handle this correctly.
Original exception was:
 Traceback (most recent call last):
  File "/Users/mhope/Documents/projects/beta-survey-django/env/lib/python3.8/site-packages/rest_framework/serializers.py", line 939, in create
    instance = ModelClass._default_manager.create(**validated_data)
  File "/Users/mhope/Documents/projects/beta-survey-django/env/lib/python3.8/site-packages/django/db/models/manager.py", line 85, in manager_method
    return getattr(self.get_queryset(), name)(*args, **kwargs)
  File "/Users/mhope/Documents/projects/beta-survey-django/env/lib/python3.8/site-packages/django/db/models/query.py", line 445, in create
    obj = self.model(**kwargs)
  File "/Users/mhope/Documents/projects/beta-survey-django/env/lib/python3.8/site-packages/django/db/models/base.py", line 501, in __init__
    raise TypeError("%s() got an unexpected keyword argument '%s'" % (cls.__name__, kwarg))
TypeError: Responses() got an unexpected keyword argument 'belive_in_hand_washing'

2020-11-15 00:51:48,512,512 MARKDOWN DEBUG Successfully imported extension module "markdown.extensions.toc".
2020-11-15 00:51:48,513,513 MARKDOWN DEBUG Successfully loaded extension "markdown.extensions.toc.TocExtension".
2020-11-15 00:52:05,729,729 urllib3.connectionpool DEBUG Starting new HTTPS connection (1): ipleak.net:443
2020-11-15 00:52:31,756,756 django.request ERROR Internal Server Error: /
Traceback (most recent call last):
  File "/Users/mhope/Documents/projects/beta-survey-django/env/lib/python3.8/site-packages/urllib3/connectionpool.py", line 670, in urlopen
    httplib_response = self._make_request(
  File "/Users/mhope/Documents/projects/beta-survey-django/env/lib/python3.8/site-packages/urllib3/connectionpool.py", line 381, in _make_request
    self._validate_conn(conn)
  File "/Users/mhope/Documents/projects/beta-survey-django/env/lib/python3.8/site-packages/urllib3/connectionpool.py", line 978, in _validate_conn
    conn.connect()
  File "/Users/mhope/Documents/projects/beta-survey-django/env/lib/python3.8/site-packages/urllib3/connection.py", line 362, in connect
    self.sock = ssl_wrap_socket(
  File "/Users/mhope/Documents/projects/beta-survey-django/env/lib/python3.8/site-packages/urllib3/util/ssl_.py", line 386, in ssl_wrap_socket
    return context.wrap_socket(sock, server_hostname=server_hostname)
  File "/Library/Developer/CommandLineTools/Library/Frameworks/Python3.framework/Versions/3.8/lib/python3.8/ssl.py", line 500, in wrap_socket
    return self.sslsocket_class._create(
  File "/Library/Developer/CommandLineTools/Library/Frameworks/Python3.framework/Versions/3.8/lib/python3.8/ssl.py", line 1040, in _create
    self.do_handshake()
  File "/Library/Developer/CommandLineTools/Library/Frameworks/Python3.framework/Versions/3.8/lib/python3.8/ssl.py", line 1309, in do_handshake
    self._sslobj.do_handshake()
ConnectionResetError: [Errno 54] Connection reset by peer

During handling of the above exception, another exception occurred:

Traceback (most recent call last):
  File "/Users/mhope/Documents/projects/beta-survey-django/env/lib/python3.8/site-packages/requests/adapters.py", line 439, in send
    resp = conn.urlopen(
  File "/Users/mhope/Documents/projects/beta-survey-django/env/lib/python3.8/site-packages/urllib3/connectionpool.py", line 726, in urlopen
    retries = retries.increment(
  File "/Users/mhope/Documents/projects/beta-survey-django/env/lib/python3.8/site-packages/urllib3/util/retry.py", line 410, in increment
    raise six.reraise(type(error), error, _stacktrace)
  File "/Users/mhope/Documents/projects/beta-survey-django/env/lib/python3.8/site-packages/urllib3/packages/six.py", line 734, in reraise
    raise value.with_traceback(tb)
  File "/Users/mhope/Documents/projects/beta-survey-django/env/lib/python3.8/site-packages/urllib3/connectionpool.py", line 670, in urlopen
    httplib_response = self._make_request(
  File "/Users/mhope/Documents/projects/beta-survey-django/env/lib/python3.8/site-packages/urllib3/connectionpool.py", line 381, in _make_request
    self._validate_conn(conn)
  File "/Users/mhope/Documents/projects/beta-survey-django/env/lib/python3.8/site-packages/urllib3/connectionpool.py", line 978, in _validate_conn
    conn.connect()
  File "/Users/mhope/Documents/projects/beta-survey-django/env/lib/python3.8/site-packages/urllib3/connection.py", line 362, in connect
    self.sock = ssl_wrap_socket(
  File "/Users/mhope/Documents/projects/beta-survey-django/env/lib/python3.8/site-packages/urllib3/util/ssl_.py", line 386, in ssl_wrap_socket
    return context.wrap_socket(sock, server_hostname=server_hostname)
  File "/Library/Developer/CommandLineTools/Library/Frameworks/Python3.framework/Versions/3.8/lib/python3.8/ssl.py", line 500, in wrap_socket
    return self.sslsocket_class._create(
  File "/Library/Developer/CommandLineTools/Library/Frameworks/Python3.framework/Versions/3.8/lib/python3.8/ssl.py", line 1040, in _create
    self.do_handshake()
  File "/Library/Developer/CommandLineTools/Library/Frameworks/Python3.framework/Versions/3.8/lib/python3.8/ssl.py", line 1309, in do_handshake
    self._sslobj.do_handshake()
urllib3.exceptions.ProtocolError: ('Connection aborted.', ConnectionResetError(54, 'Connection reset by peer'))

During handling of the above exception, another exception occurred:

Traceback (most recent call last):
  File "/Users/mhope/Documents/projects/beta-survey-django/env/lib/python3.8/site-packages/django/core/handlers/exception.py", line 47, in inner
    response = get_response(request)
  File "/Users/mhope/Documents/projects/beta-survey-django/env/lib/python3.8/site-packages/django/core/handlers/base.py", line 179, in _get_response
    response = wrapped_callback(request, *callback_args, **callback_kwargs)
  File "/Users/mhope/Documents/projects/beta-survey-django/beta-survey-django/beta_survey_django/views.py", line 48, in index
    location_request = requests.get(url = url, headers = headers)
  File "/Users/mhope/Documents/projects/beta-survey-django/env/lib/python3.8/site-packages/requests/api.py", line 76, in get
    return request('get', url, params=params, **kwargs)
  File "/Users/mhope/Documents/projects/beta-survey-django/env/lib/python3.8/site-packages/requests/api.py", line 61, in request
    return session.request(method=method, url=url, **kwargs)
  File "/Users/mhope/Documents/projects/beta-survey-django/env/lib/python3.8/site-packages/requests/sessions.py", line 530, in request
    resp = self.send(prep, **send_kwargs)
  File "/Users/mhope/Documents/projects/beta-survey-django/env/lib/python3.8/site-packages/requests/sessions.py", line 643, in send
    r = adapter.send(request, **kwargs)
  File "/Users/mhope/Documents/projects/beta-survey-django/env/lib/python3.8/site-packages/requests/adapters.py", line 498, in send
    raise ConnectionError(err, request=request)
requests.exceptions.ConnectionError: ('Connection aborted.', ConnectionResetError(54, 'Connection reset by peer'))
2020-11-15 00:52:31,805,805 urllib3.connectionpool DEBUG Starting new HTTPS connection (1): ipleak.net:443
2020-11-15 00:52:40,548,548 urllib3.connectionpool DEBUG https://ipleak.net:443 "GET /json/ HTTP/1.1" 200 None
2020-11-15 00:52:49,025,25 MARKDOWN DEBUG Successfully imported extension module "markdown.extensions.toc".
2020-11-15 00:52:49,025,25 MARKDOWN DEBUG Successfully loaded extension "markdown.extensions.toc.TocExtension".
2020-11-15 00:54:05,829,829 django.request ERROR Internal Server Error: /response
Traceback (most recent call last):
  File "/Users/mhope/Documents/projects/beta-survey-django/env/lib/python3.8/site-packages/rest_framework/serializers.py", line 939, in create
    instance = ModelClass._default_manager.create(**validated_data)
  File "/Users/mhope/Documents/projects/beta-survey-django/env/lib/python3.8/site-packages/django/db/models/manager.py", line 85, in manager_method
    return getattr(self.get_queryset(), name)(*args, **kwargs)
  File "/Users/mhope/Documents/projects/beta-survey-django/env/lib/python3.8/site-packages/django/db/models/query.py", line 445, in create
    obj = self.model(**kwargs)
  File "/Users/mhope/Documents/projects/beta-survey-django/env/lib/python3.8/site-packages/django/db/models/base.py", line 501, in __init__
    raise TypeError("%s() got an unexpected keyword argument '%s'" % (cls.__name__, kwarg))
TypeError: Responses() got an unexpected keyword argument 'belive_in_hand_washing'

During handling of the above exception, another exception occurred:

Traceback (most recent call last):
  File "/Users/mhope/Documents/projects/beta-survey-django/env/lib/python3.8/site-packages/django/core/handlers/exception.py", line 47, in inner
    response = get_response(request)
  File "/Users/mhope/Documents/projects/beta-survey-django/env/lib/python3.8/site-packages/django/core/handlers/base.py", line 179, in _get_response
    response = wrapped_callback(request, *callback_args, **callback_kwargs)
  File "/Users/mhope/Documents/projects/beta-survey-django/env/lib/python3.8/site-packages/django/views/decorators/csrf.py", line 54, in wrapped_view
    return view_func(*args, **kwargs)
  File "/Users/mhope/Documents/projects/beta-survey-django/env/lib/python3.8/site-packages/django/views/generic/base.py", line 70, in view
    return self.dispatch(request, *args, **kwargs)
  File "/Users/mhope/Documents/projects/beta-survey-django/env/lib/python3.8/site-packages/rest_framework/views.py", line 509, in dispatch
    response = self.handle_exception(exc)
  File "/Users/mhope/Documents/projects/beta-survey-django/env/lib/python3.8/site-packages/rest_framework/views.py", line 469, in handle_exception
    self.raise_uncaught_exception(exc)
  File "/Users/mhope/Documents/projects/beta-survey-django/env/lib/python3.8/site-packages/rest_framework/views.py", line 480, in raise_uncaught_exception
    raise exc
  File "/Users/mhope/Documents/projects/beta-survey-django/env/lib/python3.8/site-packages/rest_framework/views.py", line 506, in dispatch
    response = handler(request, *args, **kwargs)
  File "/Users/mhope/Documents/projects/beta-survey-django/env/lib/python3.8/site-packages/rest_framework/decorators.py", line 50, in handler
    return func(*args, **kwargs)
  File "/Users/mhope/Documents/projects/beta-survey-django/beta-survey-django/app/views.py", line 68, in response_api
    serializer.save()
  File "/Users/mhope/Documents/projects/beta-survey-django/env/lib/python3.8/site-packages/rest_framework/serializers.py", line 205, in save
    self.instance = self.create(validated_data)
  File "/Users/mhope/Documents/projects/beta-survey-django/env/lib/python3.8/site-packages/rest_framework/serializers.py", line 958, in create
    raise TypeError(msg)
TypeError: Got a `TypeError` when calling `Responses.objects.create()`. This may be because you have a writable field on the serializer class that is not a valid argument to `Responses.objects.create()`. You may need to make the field read-only, or override the ResponseSerializer.create() method to handle this correctly.
Original exception was:
 Traceback (most recent call last):
  File "/Users/mhope/Documents/projects/beta-survey-django/env/lib/python3.8/site-packages/rest_framework/serializers.py", line 939, in create
    instance = ModelClass._default_manager.create(**validated_data)
  File "/Users/mhope/Documents/projects/beta-survey-django/env/lib/python3.8/site-packages/django/db/models/manager.py", line 85, in manager_method
    return getattr(self.get_queryset(), name)(*args, **kwargs)
  File "/Users/mhope/Documents/projects/beta-survey-django/env/lib/python3.8/site-packages/django/db/models/query.py", line 445, in create
    obj = self.model(**kwargs)
  File "/Users/mhope/Documents/projects/beta-survey-django/env/lib/python3.8/site-packages/django/db/models/base.py", line 501, in __init__
    raise TypeError("%s() got an unexpected keyword argument '%s'" % (cls.__name__, kwarg))
TypeError: Responses() got an unexpected keyword argument 'belive_in_hand_washing'

2020-11-15 00:54:14,376,376 MARKDOWN DEBUG Successfully imported extension module "markdown.extensions.toc".
2020-11-15 00:54:14,376,376 MARKDOWN DEBUG Successfully loaded extension "markdown.extensions.toc.TocExtension".
2020-11-15 00:54:16,820,820 MARKDOWN DEBUG Successfully imported extension module "markdown.extensions.toc".
2020-11-15 00:54:16,820,820 MARKDOWN DEBUG Successfully loaded extension "markdown.extensions.toc.TocExtension".
2020-11-15 00:54:17,793,793 MARKDOWN DEBUG Successfully imported extension module "markdown.extensions.toc".
2020-11-15 00:54:17,793,793 MARKDOWN DEBUG Successfully loaded extension "markdown.extensions.toc.TocExtension".
2020-11-15 00:54:18,823,823 MARKDOWN DEBUG Successfully imported extension module "markdown.extensions.toc".
2020-11-15 00:54:18,824,824 MARKDOWN DEBUG Successfully loaded extension "markdown.extensions.toc.TocExtension".
2020-11-15 00:54:21,145,145 MARKDOWN DEBUG Successfully imported extension module "markdown.extensions.toc".
2020-11-15 00:54:21,145,145 MARKDOWN DEBUG Successfully loaded extension "markdown.extensions.toc.TocExtension".
2020-11-15 00:54:43,854,854 django.request ERROR Internal Server Error: /response
Traceback (most recent call last):
  File "/Users/mhope/Documents/projects/beta-survey-django/env/lib/python3.8/site-packages/rest_framework/serializers.py", line 939, in create
    instance = ModelClass._default_manager.create(**validated_data)
  File "/Users/mhope/Documents/projects/beta-survey-django/env/lib/python3.8/site-packages/django/db/models/manager.py", line 85, in manager_method
    return getattr(self.get_queryset(), name)(*args, **kwargs)
  File "/Users/mhope/Documents/projects/beta-survey-django/env/lib/python3.8/site-packages/django/db/models/query.py", line 445, in create
    obj = self.model(**kwargs)
  File "/Users/mhope/Documents/projects/beta-survey-django/env/lib/python3.8/site-packages/django/db/models/base.py", line 501, in __init__
    raise TypeError("%s() got an unexpected keyword argument '%s'" % (cls.__name__, kwarg))
TypeError: Responses() got an unexpected keyword argument 'belive_in_hand_washing'

During handling of the above exception, another exception occurred:

Traceback (most recent call last):
  File "/Users/mhope/Documents/projects/beta-survey-django/env/lib/python3.8/site-packages/django/core/handlers/exception.py", line 47, in inner
    response = get_response(request)
  File "/Users/mhope/Documents/projects/beta-survey-django/env/lib/python3.8/site-packages/django/core/handlers/base.py", line 179, in _get_response
    response = wrapped_callback(request, *callback_args, **callback_kwargs)
  File "/Users/mhope/Documents/projects/beta-survey-django/env/lib/python3.8/site-packages/django/views/decorators/csrf.py", line 54, in wrapped_view
    return view_func(*args, **kwargs)
  File "/Users/mhope/Documents/projects/beta-survey-django/env/lib/python3.8/site-packages/django/views/generic/base.py", line 70, in view
    return self.dispatch(request, *args, **kwargs)
  File "/Users/mhope/Documents/projects/beta-survey-django/env/lib/python3.8/site-packages/rest_framework/views.py", line 509, in dispatch
    response = self.handle_exception(exc)
  File "/Users/mhope/Documents/projects/beta-survey-django/env/lib/python3.8/site-packages/rest_framework/views.py", line 469, in handle_exception
    self.raise_uncaught_exception(exc)
  File "/Users/mhope/Documents/projects/beta-survey-django/env/lib/python3.8/site-packages/rest_framework/views.py", line 480, in raise_uncaught_exception
    raise exc
  File "/Users/mhope/Documents/projects/beta-survey-django/env/lib/python3.8/site-packages/rest_framework/views.py", line 506, in dispatch
    response = handler(request, *args, **kwargs)
  File "/Users/mhope/Documents/projects/beta-survey-django/env/lib/python3.8/site-packages/rest_framework/decorators.py", line 50, in handler
    return func(*args, **kwargs)
  File "/Users/mhope/Documents/projects/beta-survey-django/beta-survey-django/app/views.py", line 68, in response_api
    serializer.save()
  File "/Users/mhope/Documents/projects/beta-survey-django/env/lib/python3.8/site-packages/rest_framework/serializers.py", line 205, in save
    self.instance = self.create(validated_data)
  File "/Users/mhope/Documents/projects/beta-survey-django/env/lib/python3.8/site-packages/rest_framework/serializers.py", line 958, in create
    raise TypeError(msg)
TypeError: Got a `TypeError` when calling `Responses.objects.create()`. This may be because you have a writable field on the serializer class that is not a valid argument to `Responses.objects.create()`. You may need to make the field read-only, or override the ResponseSerializer.create() method to handle this correctly.
Original exception was:
 Traceback (most recent call last):
  File "/Users/mhope/Documents/projects/beta-survey-django/env/lib/python3.8/site-packages/rest_framework/serializers.py", line 939, in create
    instance = ModelClass._default_manager.create(**validated_data)
  File "/Users/mhope/Documents/projects/beta-survey-django/env/lib/python3.8/site-packages/django/db/models/manager.py", line 85, in manager_method
    return getattr(self.get_queryset(), name)(*args, **kwargs)
  File "/Users/mhope/Documents/projects/beta-survey-django/env/lib/python3.8/site-packages/django/db/models/query.py", line 445, in create
    obj = self.model(**kwargs)
  File "/Users/mhope/Documents/projects/beta-survey-django/env/lib/python3.8/site-packages/django/db/models/base.py", line 501, in __init__
    raise TypeError("%s() got an unexpected keyword argument '%s'" % (cls.__name__, kwarg))
TypeError: Responses() got an unexpected keyword argument 'belive_in_hand_washing'

2020-11-15 00:59:48,095,95 MARKDOWN DEBUG Successfully imported extension module "markdown.extensions.toc".
2020-11-15 00:59:48,101,101 MARKDOWN DEBUG Successfully loaded extension "markdown.extensions.toc.TocExtension".
2020-11-15 00:59:53,078,78 django.request ERROR Internal Server Error: /response
Traceback (most recent call last):
  File "/Users/mhope/Documents/projects/beta-survey-django/env/lib/python3.8/site-packages/rest_framework/serializers.py", line 939, in create
    instance = ModelClass._default_manager.create(**validated_data)
  File "/Users/mhope/Documents/projects/beta-survey-django/env/lib/python3.8/site-packages/django/db/models/manager.py", line 85, in manager_method
    return getattr(self.get_queryset(), name)(*args, **kwargs)
  File "/Users/mhope/Documents/projects/beta-survey-django/env/lib/python3.8/site-packages/django/db/models/query.py", line 445, in create
    obj = self.model(**kwargs)
  File "/Users/mhope/Documents/projects/beta-survey-django/env/lib/python3.8/site-packages/django/db/models/base.py", line 501, in __init__
    raise TypeError("%s() got an unexpected keyword argument '%s'" % (cls.__name__, kwarg))
TypeError: Responses() got an unexpected keyword argument 'belive_in_hand_washing'

During handling of the above exception, another exception occurred:

Traceback (most recent call last):
  File "/Users/mhope/Documents/projects/beta-survey-django/env/lib/python3.8/site-packages/django/core/handlers/exception.py", line 47, in inner
    response = get_response(request)
  File "/Users/mhope/Documents/projects/beta-survey-django/env/lib/python3.8/site-packages/django/core/handlers/base.py", line 179, in _get_response
    response = wrapped_callback(request, *callback_args, **callback_kwargs)
  File "/Users/mhope/Documents/projects/beta-survey-django/env/lib/python3.8/site-packages/django/views/decorators/csrf.py", line 54, in wrapped_view
    return view_func(*args, **kwargs)
  File "/Users/mhope/Documents/projects/beta-survey-django/env/lib/python3.8/site-packages/django/views/generic/base.py", line 70, in view
    return self.dispatch(request, *args, **kwargs)
  File "/Users/mhope/Documents/projects/beta-survey-django/env/lib/python3.8/site-packages/rest_framework/views.py", line 509, in dispatch
    response = self.handle_exception(exc)
  File "/Users/mhope/Documents/projects/beta-survey-django/env/lib/python3.8/site-packages/rest_framework/views.py", line 469, in handle_exception
    self.raise_uncaught_exception(exc)
  File "/Users/mhope/Documents/projects/beta-survey-django/env/lib/python3.8/site-packages/rest_framework/views.py", line 480, in raise_uncaught_exception
    raise exc
  File "/Users/mhope/Documents/projects/beta-survey-django/env/lib/python3.8/site-packages/rest_framework/views.py", line 506, in dispatch
    response = handler(request, *args, **kwargs)
  File "/Users/mhope/Documents/projects/beta-survey-django/env/lib/python3.8/site-packages/rest_framework/decorators.py", line 50, in handler
    return func(*args, **kwargs)
  File "/Users/mhope/Documents/projects/beta-survey-django/beta-survey-django/app/views.py", line 68, in response_api
    serializer.save()
  File "/Users/mhope/Documents/projects/beta-survey-django/env/lib/python3.8/site-packages/rest_framework/serializers.py", line 205, in save
    self.instance = self.create(validated_data)
  File "/Users/mhope/Documents/projects/beta-survey-django/env/lib/python3.8/site-packages/rest_framework/serializers.py", line 958, in create
    raise TypeError(msg)
TypeError: Got a `TypeError` when calling `Responses.objects.create()`. This may be because you have a writable field on the serializer class that is not a valid argument to `Responses.objects.create()`. You may need to make the field read-only, or override the ResponseSerializer.create() method to handle this correctly.
Original exception was:
 Traceback (most recent call last):
  File "/Users/mhope/Documents/projects/beta-survey-django/env/lib/python3.8/site-packages/rest_framework/serializers.py", line 939, in create
    instance = ModelClass._default_manager.create(**validated_data)
  File "/Users/mhope/Documents/projects/beta-survey-django/env/lib/python3.8/site-packages/django/db/models/manager.py", line 85, in manager_method
    return getattr(self.get_queryset(), name)(*args, **kwargs)
  File "/Users/mhope/Documents/projects/beta-survey-django/env/lib/python3.8/site-packages/django/db/models/query.py", line 445, in create
    obj = self.model(**kwargs)
  File "/Users/mhope/Documents/projects/beta-survey-django/env/lib/python3.8/site-packages/django/db/models/base.py", line 501, in __init__
    raise TypeError("%s() got an unexpected keyword argument '%s'" % (cls.__name__, kwarg))
TypeError: Responses() got an unexpected keyword argument 'belive_in_hand_washing'

2020-11-15 01:00:56,138,138 django.utils.autoreload INFO /Users/mhope/Documents/projects/beta-survey-django/beta-survey-django/app/views.py changed, reloading.
2020-11-15 01:00:56,139,139 asyncio DEBUG Using selector: KqueueSelector
2020-11-15 01:01:06,060,60 MARKDOWN DEBUG Successfully imported extension module "markdown.extensions.toc".
2020-11-15 01:01:06,060,60 MARKDOWN DEBUG Successfully loaded extension "markdown.extensions.toc.TocExtension".
2020-11-15 01:01:12,311,311 django.request ERROR Internal Server Error: /response
Traceback (most recent call last):
  File "/Users/mhope/Documents/projects/beta-survey-django/env/lib/python3.8/site-packages/rest_framework/serializers.py", line 939, in create
    instance = ModelClass._default_manager.create(**validated_data)
  File "/Users/mhope/Documents/projects/beta-survey-django/env/lib/python3.8/site-packages/django/db/models/manager.py", line 85, in manager_method
    return getattr(self.get_queryset(), name)(*args, **kwargs)
  File "/Users/mhope/Documents/projects/beta-survey-django/env/lib/python3.8/site-packages/django/db/models/query.py", line 445, in create
    obj = self.model(**kwargs)
  File "/Users/mhope/Documents/projects/beta-survey-django/env/lib/python3.8/site-packages/django/db/models/base.py", line 501, in __init__
    raise TypeError("%s() got an unexpected keyword argument '%s'" % (cls.__name__, kwarg))
TypeError: Responses() got an unexpected keyword argument 'belive_in_hand_washing'

During handling of the above exception, another exception occurred:

Traceback (most recent call last):
  File "/Users/mhope/Documents/projects/beta-survey-django/env/lib/python3.8/site-packages/django/core/handlers/exception.py", line 47, in inner
    response = get_response(request)
  File "/Users/mhope/Documents/projects/beta-survey-django/env/lib/python3.8/site-packages/django/core/handlers/base.py", line 179, in _get_response
    response = wrapped_callback(request, *callback_args, **callback_kwargs)
  File "/Users/mhope/Documents/projects/beta-survey-django/env/lib/python3.8/site-packages/django/views/decorators/csrf.py", line 54, in wrapped_view
    return view_func(*args, **kwargs)
  File "/Users/mhope/Documents/projects/beta-survey-django/env/lib/python3.8/site-packages/django/views/generic/base.py", line 70, in view
    return self.dispatch(request, *args, **kwargs)
  File "/Users/mhope/Documents/projects/beta-survey-django/env/lib/python3.8/site-packages/rest_framework/views.py", line 509, in dispatch
    response = self.handle_exception(exc)
  File "/Users/mhope/Documents/projects/beta-survey-django/env/lib/python3.8/site-packages/rest_framework/views.py", line 469, in handle_exception
    self.raise_uncaught_exception(exc)
  File "/Users/mhope/Documents/projects/beta-survey-django/env/lib/python3.8/site-packages/rest_framework/views.py", line 480, in raise_uncaught_exception
    raise exc
  File "/Users/mhope/Documents/projects/beta-survey-django/env/lib/python3.8/site-packages/rest_framework/views.py", line 506, in dispatch
    response = handler(request, *args, **kwargs)
  File "/Users/mhope/Documents/projects/beta-survey-django/env/lib/python3.8/site-packages/rest_framework/decorators.py", line 50, in handler
    return func(*args, **kwargs)
  File "/Users/mhope/Documents/projects/beta-survey-django/beta-survey-django/app/views.py", line 68, in response_api
    serializer.save()
  File "/Users/mhope/Documents/projects/beta-survey-django/env/lib/python3.8/site-packages/rest_framework/serializers.py", line 205, in save
    self.instance = self.create(validated_data)
  File "/Users/mhope/Documents/projects/beta-survey-django/env/lib/python3.8/site-packages/rest_framework/serializers.py", line 958, in create
    raise TypeError(msg)
TypeError: Got a `TypeError` when calling `Responses.objects.create()`. This may be because you have a writable field on the serializer class that is not a valid argument to `Responses.objects.create()`. You may need to make the field read-only, or override the ResponseSerializer.create() method to handle this correctly.
Original exception was:
 Traceback (most recent call last):
  File "/Users/mhope/Documents/projects/beta-survey-django/env/lib/python3.8/site-packages/rest_framework/serializers.py", line 939, in create
    instance = ModelClass._default_manager.create(**validated_data)
  File "/Users/mhope/Documents/projects/beta-survey-django/env/lib/python3.8/site-packages/django/db/models/manager.py", line 85, in manager_method
    return getattr(self.get_queryset(), name)(*args, **kwargs)
  File "/Users/mhope/Documents/projects/beta-survey-django/env/lib/python3.8/site-packages/django/db/models/query.py", line 445, in create
    obj = self.model(**kwargs)
  File "/Users/mhope/Documents/projects/beta-survey-django/env/lib/python3.8/site-packages/django/db/models/base.py", line 501, in __init__
    raise TypeError("%s() got an unexpected keyword argument '%s'" % (cls.__name__, kwarg))
TypeError: Responses() got an unexpected keyword argument 'belive_in_hand_washing'

2020-11-15 01:01:23,162,162 asyncio DEBUG Using selector: KqueueSelector
2020-11-15 01:01:50,228,228 asyncio DEBUG Using selector: KqueueSelector
2020-11-15 01:02:15,644,644 asyncio DEBUG Using selector: KqueueSelector
2020-11-15 01:02:24,616,616 MARKDOWN DEBUG Successfully imported extension module "markdown.extensions.toc".
2020-11-15 01:02:24,617,617 MARKDOWN DEBUG Successfully loaded extension "markdown.extensions.toc.TocExtension".
2020-11-15 01:04:14,257,257 MARKDOWN DEBUG Successfully imported extension module "markdown.extensions.toc".
2020-11-15 01:04:14,258,258 MARKDOWN DEBUG Successfully loaded extension "markdown.extensions.toc.TocExtension".
2020-11-15 01:04:14,278,278 django.request WARNING Bad Request: /response
2020-11-15 01:04:50,077,77 django.utils.autoreload INFO /Users/mhope/Documents/projects/beta-survey-django/beta-survey-django/app/serializers.py changed, reloading.
2020-11-15 01:04:50,078,78 asyncio DEBUG Using selector: KqueueSelector
2020-11-15 01:04:54,720,720 django.utils.autoreload INFO /Users/mhope/Documents/projects/beta-survey-django/beta-survey-django/app/serializers.py changed, reloading.
2020-11-15 01:04:54,721,721 asyncio DEBUG Using selector: KqueueSelector
2020-11-15 01:05:11,086,86 django.utils.autoreload INFO /Users/mhope/Documents/projects/beta-survey-django/beta-survey-django/app/serializers.py changed, reloading.
2020-11-15 01:05:11,087,87 asyncio DEBUG Using selector: KqueueSelector
2020-11-15 01:05:16,980,980 asyncio DEBUG Using selector: KqueueSelector
2020-11-15 01:05:27,824,824 asyncio DEBUG Using selector: KqueueSelector
2020-11-15 01:06:01,797,797 MARKDOWN DEBUG Successfully imported extension module "markdown.extensions.toc".
2020-11-15 01:06:01,797,797 MARKDOWN DEBUG Successfully loaded extension "markdown.extensions.toc.TocExtension".
2020-11-15 01:06:12,937,937 urllib3.connectionpool DEBUG Starting new HTTPS connection (1): ipleak.net:443
2020-11-15 01:06:20,516,516 urllib3.connectionpool DEBUG https://ipleak.net:443 "GET /json/ HTTP/1.1" 200 None
2020-11-15 01:06:35,315,315 urllib3.connectionpool DEBUG Starting new HTTPS connection (1): deywuro.com:443
2020-11-15 01:06:36,311,311 urllib3.connectionpool DEBUG https://deywuro.com:443 "GET /api/sms?username=sammy&password=suppORT_pass_0987&source=Test&destination=0556581928&message=Your+OTP+is+940427 HTTP/1.1" 200 None
2020-11-15 01:07:58,803,803 django.request WARNING Bad Request: /response
2020-11-15 01:09:27,275,275 asyncio DEBUG Using selector: KqueueSelector
2020-11-15 01:09:43,512,512 asyncio DEBUG Using selector: KqueueSelector
2020-11-15 01:09:51,668,668 asyncio DEBUG Using selector: KqueueSelector
2020-11-15 01:15:11,482,482 django.request WARNING Bad Request: /response
2020-11-15 01:17:27,773,773 asyncio DEBUG Using selector: KqueueSelector
2020-11-15 01:19:57,869,869 django.request WARNING Bad Request: /response
2020-11-15 01:20:56,768,768 django.utils.autoreload INFO /Users/mhope/Documents/projects/beta-survey-django/beta-survey-django/app/serializers.py changed, reloading.
2020-11-15 01:20:56,769,769 asyncio DEBUG Using selector: KqueueSelector
2020-11-15 01:21:56,473,473 django.request ERROR Internal Server Error: /response
Traceback (most recent call last):
  File "/Users/mhope/Documents/projects/beta-survey-django/env/lib/python3.8/site-packages/rest_framework/serializers.py", line 939, in create
    instance = ModelClass._default_manager.create(**validated_data)
  File "/Users/mhope/Documents/projects/beta-survey-django/env/lib/python3.8/site-packages/django/db/models/manager.py", line 85, in manager_method
    return getattr(self.get_queryset(), name)(*args, **kwargs)
  File "/Users/mhope/Documents/projects/beta-survey-django/env/lib/python3.8/site-packages/django/db/models/query.py", line 445, in create
    obj = self.model(**kwargs)
  File "/Users/mhope/Documents/projects/beta-survey-django/env/lib/python3.8/site-packages/django/db/models/base.py", line 501, in __init__
    raise TypeError("%s() got an unexpected keyword argument '%s'" % (cls.__name__, kwarg))
TypeError: Responses() got an unexpected keyword argument 'belive_in_hand_washing'

During handling of the above exception, another exception occurred:

Traceback (most recent call last):
  File "/Users/mhope/Documents/projects/beta-survey-django/env/lib/python3.8/site-packages/django/core/handlers/exception.py", line 47, in inner
    response = get_response(request)
  File "/Users/mhope/Documents/projects/beta-survey-django/env/lib/python3.8/site-packages/django/core/handlers/base.py", line 179, in _get_response
    response = wrapped_callback(request, *callback_args, **callback_kwargs)
  File "/Users/mhope/Documents/projects/beta-survey-django/env/lib/python3.8/site-packages/django/views/decorators/csrf.py", line 54, in wrapped_view
    return view_func(*args, **kwargs)
  File "/Users/mhope/Documents/projects/beta-survey-django/env/lib/python3.8/site-packages/django/views/generic/base.py", line 70, in view
    return self.dispatch(request, *args, **kwargs)
  File "/Users/mhope/Documents/projects/beta-survey-django/env/lib/python3.8/site-packages/rest_framework/views.py", line 509, in dispatch
    response = self.handle_exception(exc)
  File "/Users/mhope/Documents/projects/beta-survey-django/env/lib/python3.8/site-packages/rest_framework/views.py", line 469, in handle_exception
    self.raise_uncaught_exception(exc)
  File "/Users/mhope/Documents/projects/beta-survey-django/env/lib/python3.8/site-packages/rest_framework/views.py", line 480, in raise_uncaught_exception
    raise exc
  File "/Users/mhope/Documents/projects/beta-survey-django/env/lib/python3.8/site-packages/rest_framework/views.py", line 506, in dispatch
    response = handler(request, *args, **kwargs)
  File "/Users/mhope/Documents/projects/beta-survey-django/env/lib/python3.8/site-packages/rest_framework/decorators.py", line 50, in handler
    return func(*args, **kwargs)
  File "/Users/mhope/Documents/projects/beta-survey-django/beta-survey-django/app/views.py", line 68, in response_api
    serializer.save()
  File "/Users/mhope/Documents/projects/beta-survey-django/env/lib/python3.8/site-packages/rest_framework/serializers.py", line 205, in save
    self.instance = self.create(validated_data)
  File "/Users/mhope/Documents/projects/beta-survey-django/env/lib/python3.8/site-packages/rest_framework/serializers.py", line 958, in create
    raise TypeError(msg)
TypeError: Got a `TypeError` when calling `Responses.objects.create()`. This may be because you have a writable field on the serializer class that is not a valid argument to `Responses.objects.create()`. You may need to make the field read-only, or override the ResponseSerializer.create() method to handle this correctly.
Original exception was:
 Traceback (most recent call last):
  File "/Users/mhope/Documents/projects/beta-survey-django/env/lib/python3.8/site-packages/rest_framework/serializers.py", line 939, in create
    instance = ModelClass._default_manager.create(**validated_data)
  File "/Users/mhope/Documents/projects/beta-survey-django/env/lib/python3.8/site-packages/django/db/models/manager.py", line 85, in manager_method
    return getattr(self.get_queryset(), name)(*args, **kwargs)
  File "/Users/mhope/Documents/projects/beta-survey-django/env/lib/python3.8/site-packages/django/db/models/query.py", line 445, in create
    obj = self.model(**kwargs)
  File "/Users/mhope/Documents/projects/beta-survey-django/env/lib/python3.8/site-packages/django/db/models/base.py", line 501, in __init__
    raise TypeError("%s() got an unexpected keyword argument '%s'" % (cls.__name__, kwarg))
TypeError: Responses() got an unexpected keyword argument 'belive_in_hand_washing'

2020-11-15 01:22:17,842,842 urllib3.connectionpool DEBUG Starting new HTTPS connection (1): ipleak.net:443
2020-11-15 01:22:20,751,751 urllib3.connectionpool DEBUG https://ipleak.net:443 "GET /json/ HTTP/1.1" 200 None
2020-11-15 01:23:44,122,122 django.utils.autoreload INFO /Users/mhope/Documents/projects/beta-survey-django/beta-survey-django/app/serializers.py changed, reloading.
2020-11-15 01:23:44,123,123 asyncio DEBUG Using selector: KqueueSelector
2020-11-15 01:23:47,223,223 asyncio DEBUG Using selector: KqueueSelector
2020-11-15 01:25:11,524,524 urllib3.connectionpool DEBUG Starting new HTTPS connection (1): ipleak.net:443
2020-11-15 01:25:12,719,719 urllib3.connectionpool DEBUG https://ipleak.net:443 "GET /json/ HTTP/1.1" 200 None
2020-11-15 01:25:23,559,559 urllib3.connectionpool DEBUG Starting new HTTPS connection (1): deywuro.com:443
2020-11-15 01:25:25,316,316 urllib3.connectionpool DEBUG https://deywuro.com:443 "GET /api/sms?username=sammy&password=suppORT_pass_0987&source=Test&destination=0556581928&message=Your+OTP+is+284679 HTTP/1.1" 200 None
2020-11-15 01:28:25,757,757 urllib3.connectionpool DEBUG Starting new HTTPS connection (1): ipleak.net:443
2020-11-15 01:28:28,872,872 urllib3.connectionpool DEBUG https://ipleak.net:443 "GET /json/ HTTP/1.1" 200 None
2020-11-15 01:28:39,205,205 urllib3.connectionpool DEBUG Starting new HTTPS connection (1): deywuro.com:443
2020-11-15 01:28:41,160,160 urllib3.connectionpool DEBUG https://deywuro.com:443 "GET /api/sms?username=sammy&password=suppORT_pass_0987&source=Test&destination=0556581928&message=Your+OTP+is+479939 HTTP/1.1" 200 None
2020-11-15 01:29:50,919,919 django.request WARNING Bad Request: /response
2020-11-15 01:32:17,856,856 urllib3.connectionpool DEBUG Starting new HTTPS connection (1): ipleak.net:443
2020-11-15 01:32:20,301,301 urllib3.connectionpool DEBUG https://ipleak.net:443 "GET /json/ HTTP/1.1" 200 None
2020-11-15 01:32:57,199,199 django.security.csrf WARNING Forbidden (CSRF token missing or incorrect.): /
2020-11-15 01:33:13,004,4 urllib3.connectionpool DEBUG Starting new HTTPS connection (1): ipleak.net:443
2020-11-15 01:33:17,874,874 urllib3.connectionpool DEBUG https://ipleak.net:443 "GET /json/ HTTP/1.1" 200 None
2020-11-15 01:33:28,251,251 urllib3.connectionpool DEBUG Starting new HTTPS connection (1): deywuro.com:443
2020-11-15 01:33:29,702,702 urllib3.connectionpool DEBUG https://deywuro.com:443 "GET /api/sms?username=sammy&password=suppORT_pass_0987&source=Test&destination=0556581928&message=Your+OTP+is+149723 HTTP/1.1" 200 None
2020-11-15 01:36:37,837,837 urllib3.connectionpool DEBUG Starting new HTTPS connection (1): ipleak.net:443
2020-11-15 01:36:40,109,109 urllib3.connectionpool DEBUG https://ipleak.net:443 "GET /json/ HTTP/1.1" 200 None
2020-11-15 01:47:44,524,524 django.utils.autoreload INFO /Users/mhope/Documents/projects/beta-survey-django/beta-survey-django/user_app/views.py changed, reloading.
2020-11-15 01:47:44,526,526 asyncio DEBUG Using selector: KqueueSelector
2020-11-15 01:58:01,549,549 django.utils.autoreload INFO /Users/mhope/Documents/projects/beta-survey-django/beta-survey-django/user_app/views.py changed, reloading.
2020-11-15 01:58:01,551,551 asyncio DEBUG Using selector: KqueueSelector
2020-11-15 01:58:07,633,633 django.utils.autoreload INFO /Users/mhope/Documents/projects/beta-survey-django/beta-survey-django/user_app/views.py changed, reloading.
2020-11-15 01:58:07,633,633 asyncio DEBUG Using selector: KqueueSelector
2020-11-15 01:58:16,554,554 django.utils.autoreload INFO /Users/mhope/Documents/projects/beta-survey-django/beta-survey-django/user_app/views.py changed, reloading.
2020-11-15 01:58:16,555,555 asyncio DEBUG Using selector: KqueueSelector
2020-11-15 01:58:20,159,159 django.utils.autoreload INFO /Users/mhope/Documents/projects/beta-survey-django/beta-survey-django/user_app/views.py changed, reloading.
2020-11-15 01:58:20,161,161 asyncio DEBUG Using selector: KqueueSelector
2020-11-15 02:21:39,416,416 asyncio DEBUG Using selector: KqueueSelector
2020-11-15 02:27:02,960,960 asyncio DEBUG Using selector: KqueueSelector
